Workbook

Sheet storms - seasonal amp funct
A1: Storm 2 | B1: =MAX(B3:B94) -> 0.02275734 | C1: Mobile | D1: Total (Reconstructed) | J1: Storm 3 | K1: =MAX(K3:K99) -> 0.039279705 | L1: Mobile | M1: Total | S1: Storm 4 | T1: =MAX(T3:T100) -> 0.18100711 | U1: Mobile | V1: Total | AB1: Storm 5 | AC1: =MAX(AC3:AC100) -> 0.0051704169 | AD1: Total | AJ1: Storm 6 | AK1: =MAX(AK3:AK99) -> 0.021282733 | AL1: Total | AR1: Storm 7 | AS1: =MAX(AS3:AS99) -> 0.02757667 | AT1: Mobile | AU1: Total | BA1: Spring | BC1: Mobile | BD1: Total
A2: Time | B2: Max Amp | C2: Tau (Pa) | D2: Tau (Pa) | E2: Ch1 Impulses | F2: Imp/s | G2: Imp/s * MaxAmp | H2: Dmax (mm) | J2: Time | K2: Max Amp | L2: Tau (Pa) | M2: Tau (Pa) | N2: Ch1 Impulses | O2: Impulses/s | P2: Imp/s * MaxAmp | Q2: Dmax (mm) | S2: Time | T2: Max Amp | U2: Tau (Pa) | V2: Tau (Pa) | W2: Ch1 Impulses | X2: Impulses/s | Y2: Imp/s * MaxAmp | Z2: Dmax (mm) | AB2: Time | AC2: Max Amp | AD2: Tau (Pa) | AE2: Ch1 Impulses | AF2: Impulses/s | AG2: Imp/s * MaxAmp | AH2: Dmax (mm) | AJ2: Time | AK2: Max Amp | AL2: Tau (Pa) | AM2: Ch1 Impulses | AN2: Impulses/s | AO2: Imp/s * MaxAmp | AP2: Dmax (mm) | AR2: Time | AS2: Max Amp | AT2: Tau (Pa) | AU2: Tau (Pa) | AV2: Ch1 Impulses | AW2: Impulses/s | AX2: Imp/s * MaxAmp | AY2: Dmax (mm) | BA2: Time | BB2: Max Amp | BC2: Tau (Pa) | BD2: Tau (Pa) | BE2: Ch1 Impulses | BF2: Impulses/s | BG2: Imp/s * MaxAmp | BH2: Dmax (mm)
A3: 44776.001 | B3: 1.4221254e-07 | C3: 0.76957219 | D3: 59.870983 | E3: 0 | F3: =E3/60 -> 0 | G3: =F3*B3 -> 0 | H3: =17.285*G3^0.664 -> 0 | J3: 44781.001 | K3: 2.1407756e-06 | L3: 1.4441644 | M3: 61.528936 | N3: 0 | O3: =N3/60 -> 0 | P3: =O3*K3 -> 0 | Q3: =17.285*P3^0.664 -> 0 | S3: 45136 | T3: 0.00079727119 | U3: 0.85462156 | V3: 63.118783 | W3: 1210 | X3: =W3/60 -> 20.166667 | Y3: =T3*X3 -> 0.016078302 | Z3: =17.285*Y3^0.664 -> 1.1133017 | AB3: 45151 | AC3: 0.00053610418 | AD3: 62.63066 | AE3: 192 | AF3: =AE3/60 -> 3.2 | AG3: =AF3*AC3 -> 0.0017155334 | AH3: =17.285*AG3^0.664 -> 0.25194772 | AJ3: 45166 | AK3: 0.00096064495 | AL3: 62.340176 | AM3: 1103 | AN3: =AM3/60 -> 18.383333 | AO3: =AN3*AK3 -> 0.017659856 | AP3: =17.285*AO3^0.664 -> 1.184865 | AR3: 45183 | AS3: 0.0005654558 | AT3: 0.44939224 | AU3: 63.318501 | AV3: 585 | AW3: =AV3/60 -> 9.75 | AX3: =AW3*AS3 -> 0.0055131941 | AY3: =17.285*AX3^0.664 -> 0.54696705 | BA3: 45030.719 | BB3: 0.0049261644 | BC3: 53.134964 | BD3: 105.52 | BE3: 38932 | BF3: =BE3/60 -> 648.86667 | BG3: =BF3*BB3 -> 3.1964239 | BH3: =17.285*BG3^0.664 -> 37.390952
A4: 44776.011 | B4: 1.7972696e-07 | C4: 0.77181716 | D4: 59.870983 | E4: 0 | F4: =E4/60 -> 0 | G4: =F4*B4 -> 0 | H4: =17.285*G4^0.664 -> 0 | J4: 44781.011 | K4: 2.4997227e-06 | L4: 1.5123823 | M4: 61.528936 | N4: 0 | O4: =N4/60 -> 0 | P4: =O4*K4 -> 0 | Q4: =17.285*P4^0.664 -> 0 | S4: 45136.01 | T4: 0.0010779218 | U4: 0.99067577 | V4: 63.193742 | W4: 2773 | X4: =W4/60 -> 46.216667 | Y4: =T4*X4 -> 0.049817951 | Z4: =17.285*Y4^0.664 -> 2.3590307 | AB4: 45151.01 | AC4: 0.0009235617 | AD4: 62.63066 | AE4: 1344 | AF4: =AE4/60 -> 22.4 | AG4: =AF4*AC4 -> 0.020687782 | AH4: =17.285*AG4^0.664 -> 1.3161441 | AJ4: 45166.01 | AK4: 0.0016569484 | AL4: 62.459047 | AM4: 3754 | AN4: =AM4/60 -> 62.566667 | AO4: =AN4*AK4 -> 0.10366974 | AP4: =17.285*AO4^0.664 -> 3.837623 | AR4: 45183.01 | AS4: 0.00090926173 | AT4: 0.44939224 | AU4: 63.430441 | AV4: 770 | AW4: =AV4/60 -> 12.833333 | AX4: =AW4*AS4 -> 0.011668859 | AY4: =17.285*AX4^0.664 -> 0.89986267 | BA4: 45030.729 | BB4: 0.0046821063 | BC4: 62.31528 | BD4: 105.79 | BE4: 38800 | BF4: =BE4/60 -> 646.66667 | BG4: =BF4*BB4 -> 3.0277621 | BH4: =17.285*BG4^0.664 -> 36.06901
A5: 44776.022 | B5: 1.6958202e-07 | C5: 0.78552174 | D5: 59.870983 | E5: 0 | F5: =E5/60 -> 0 | G5: =F5*B5 -> 0 | H5: =17.285*G5^0.664 -> 0 | J5: 44781.022 | K5: 1.8784161e-06 | L5: 1.353318 | M5: 61.540376 | N5: 0 | O5: =N5/60 -> 0 | P5: =O5*K5 -> 0 | Q5: =17.285*P5^0.664 -> 0 | S5: 45136.021 | T5: 0.0015781421 | U5: 1.1441743 | V5: 63.263481 | W5: 4656 | X5: =W5/60 -> 77.6 | Y5: =T5*X5 -> 0.12246383 | Z5: =17.285*Y5^0.664 -> 4.2865371 | AB5: 45151.021 | AC5: 0.00072240959 | AD5: 62.631509 | AE5: 341 | AF5: =AE5/60 -> 5.6833333 | AG5: =AF5*AC5 -> 0.0041056945 | AH5: =17.285*AG5^0.664 -> 0.44973647 | AJ5: 45166.021 | AK5: 0.0012295281 | AL5: 62.459047 | AM5: 2081 | AN5: =AM5/60 -> 34.683333 | AO5: =AN5*AK5 -> 0.042644134 | AP5: =17.285*AO5^0.664 -> 2.1276293 | AR5: 45183.021 | AS5: 0.0006561637 | AT5: 0.44894941 | AU5: 63.497009 | AV5: 772 | AW5: =AV5/60 -> 12.866667 | AX5: =AW5*AS5 -> 0.0084426395 | AY5: =17.285*AX5^0.664 -> 0.72585678 | BA5: 45030.74 | BB5: 0.0044436656 | BC5: 55.160894 | BD5: 106.5 | BE5: 40053 | BF5: =BE5/60 -> 667.55 | BG5: =BF5*BB5 -> 2.9663689 | BH5: =17.285*BG5^0.664 -> 35.581716
A6: 44776.032 | B6: 1.5283904e-07 | C6: 0.77333739 | D6: 59.914456 | E6: 0 | F6: =E6/60 -> 0 | G6: =F6*B6 -> 0 | H6: =17.285*G6^0.664 -> 0 | J6: 44781.032 | K6: 1.2574265e-06 | L6: 1.3056303 | M6: 61.581804 | N6: 0 | O6: =N6/60 -> 0 | P6: =O6*K6 -> 0 | Q6: =17.285*P6^0.664 -> 0 | S6: 45136.031 | T6: 0.00068311164 | U6: 0.73432994 | V6: 63.263481 | W6: 708 | X6: =W6/60 -> 11.8 | Y6: =T6*X6 -> 0.0080607174 | Z6: =17.285*Y6^0.664 -> 0.70388469 | AB6: 45151.031 | AC6: 0.0011939513 | AD6: 62.631509 | AE6: 1056 | AF6: =AE6/60 -> 17.6 | AG6: =AF6*AC6 -> 0.021013544 | AH6: =17.285*AG6^0.664 -> 1.3298692 | AJ6: 45166.031 | AK6: 0.0019041151 | AL6: 62.459047 | AM6: 2605 | AN6: =AM6/60 -> 43.416667 | AO6: =AN6*AK6 -> 0.082670332 | AP6: =17.285*AO6^0.664 -> 3.3020951 | AR6: 45183.031 | AS6: 0.0010348934 | AT6: 0.59425535 | AU6: 63.505989 | AV6: 1352 | AW6: =AV6/60 -> 22.533333 | AX6: =AW6*AS6 -> 0.023319598 | AY6: =17.285*AX6^0.664 -> 1.4250699 | BA6: 45030.75 | BB6: 0.0048599886 | BC6: 60.419667 | BD6: 107.06 | BE6: 39443 | BF6: =BE6/60 -> 657.38333 | BG6: =BF6*BB6 -> 3.1948755 | BH6: =17.285*BG6^0.664 -> 37.378925
A7: 44776.042 | B7: 1.0321196e-07 | C7: 0.69855225 | D7: 59.934979 | E7: 0 | F7: =E7/60 -> 0 | G7: =F7*B7 -> 0 | H7: =17.285*G7^0.664 -> 0 | J7: 44781.042 | K7: 1.816369e-06 | L7: 1.3930698 | M7: 61.635431 | N7: 0 | O7: =N7/60 -> 0 | P7: =O7*K7 -> 0 | Q7: =17.285*P7^0.664 -> 0 | S7: 45136.042 | T7: 0.0017940067 | U7: 1.3171011 | V7: 63.302307 | W7: 8187 | X7: =W7/60 -> 136.45 | Y7: =T7*X7 -> 0.24479221 | Z7: =17.285*Y7^0.664 -> 6.7893936 | AB7: 45151.042 | AC7: 0.001095427 | AD7: 62.631509 | AE7: 1099 | AF7: =AE7/60 -> 18.316667 | AG7: =AF7*AC7 -> 0.020064571 | AH7: =17.285*AG7^0.664 -> 1.2896826 | AJ7: 45166.042 | AK7: 0.0015699072 | AL7: 62.459047 | AM7: 2747 | AN7: =AM7/60 -> 45.783333 | AO7: =AN7*AK7 -> 0.071875583 | AP7: =17.285*AO7^0.664 -> 3.0091194 | AR7: 45183.042 | AS7: 0.00077285932 | AT7: 0.39993655 | AU7: 63.497009 | AV7: 607 | AW7: =AV7/60 -> 10.116667 | AX7: =AW7*AS7 -> 0.0078187601 | AY7: =17.285*AX7^0.664 -> 0.68978372 | BA7: 45030.76 | BB7: 0.004960076 | BC7: 60.419667 | BD7: 107.06 | BE7: 40541 | BF7: =BE7/60 -> 675.68333 | BG7: =BF7*BB7 -> 3.3514407 | BH7: =17.285*BG7^0.664 -> 38.58541
A8: 44776.053 | B8: 9.9320848e-08 | C8: 0.7122607 | D8: 59.986602 | E8: 0 | F8: =E8/60 -> 0 | G8: =F8*B8 -> 0 | H8: =17.285*G8^0.664 -> 0 | J8: 44781.053 | K8: 1.4770032e-06 | L8: 1.3576383 | M8: 61.699658 | N8: 0 | O8: =N8/60 -> 0 | P8: =O8*K8 -> 0 | Q8: =17.285*P8^0.664 -> 0 | S8: 45136.052 | T8: 0.001766734 | U8: 1.1441743 | V8: 63.341132 | W8: 4732 | X8: =W8/60 -> 78.866667 | Y8: =T8*X8 -> 0.13933642 | Z8: =17.285*Y8^0.664 -> 4.6701229 | AB8: 45151.052 | AC8: 0.00072396445 | AD8: 62.631509 | AE8: 745 | AF8: =AE8/60 -> 12.416667 | AG8: =AF8*AC8 -> 0.0089892252 | AH8: =17.285*AG8^0.664 -> 0.75673003 | AJ8: 45166.052 | AK8: 0.0016834227 | AL8: 62.597895 | AM8: 3159 | AN8: =AM8/60 -> 52.65 | AO8: =AN8*AK8 -> 0.088632207 | AP8: =17.285*AO8^0.664 -> 3.4583598 | AR8: 45183.052 | AS8: 0.00097552077 | AT8: 0.50323378 | AU8: 63.441227 | AV8: 1183 | AW8: =AV8/60 -> 19.716667 | AX8: =AW8*AS8 -> 0.019234018 | AY8: =17.285*AX8^0.664 -> 1.2539836 | BA8: 45030.771 | BB8: 0.005001536 | BC8: 59.125991 | BD8: 107.14 | BE8: 40146 | BF8: =BE8/60 -> 669.1 | BG8: =BF8*BB8 -> 3.3465277 | BH8: =17.285*BG8^0.664 -> 38.547843
A9: 44776.063 | B9: 1.5051816e-07 | C9: 0.77359222 | D9: 59.914456 | E9: 0 | F9: =E9/60 -> 0 | G9: =F9*B9 -> 0 | H9: =17.285*G9^0.664 -> 0 | J9: 44781.063 | K9: 1.8476866e-06 | L9: 1.3626813 | M9: 61.699658 | N9: 0 | O9: =N9/60 -> 0 | P9: =O9*K9 -> 0 | Q9: =17.285*P9^0.664 -> 0 | S9: 45136.062 | T9: 0.0017923717 | U9: 1.25751 | V9: 63.341132 | W9: 7451 | X9: =W9/60 -> 124.18333 | Y9: =T9*X9 -> 0.2225827 | Z9: =17.285*Y9^0.664 -> 6.3738769 | AB9: 45151.062 | AC9: 0.00078091567 | AD9: 62.631509 | AE9: 772 | AF9: =AE9/60 -> 12.866667 | AG9: =AF9*AC9 -> 0.010047782 | AH9: =17.285*AG9^0.664 -> 0.81478681 | AJ9: 45166.062 | AK9: 0.0012457717 | AL9: 62.597895 | AM9: 2182 | AN9: =AM9/60 -> 36.366667 | AO9: =AN9*AK9 -> 0.045304566 | AP9: =17.285*AO9^0.664 -> 2.214867 | AR9: 45183.062 | AS9: 0.00096439394 | AT9: 0.53251963 | AU9: 63.497009 | AV9: 1217 | AW9: =AV9/60 -> 20.283333 | AX9: =AW9*AS9 -> 0.019561124 | AY9: =17.285*AX9^0.664 -> 1.268104 | BA9: 45030.781 | BB9: 0.0049705824 | BC9: 62.31528 | BD9: 107.28 | BE9: 40598 | BF9: =BE9/60 -> 676.63333 | BG9: =BF9*BB9 -> 3.3632617 | BH9: =17.285*BG9^0.664 -> 38.675725
A10: 44776.074 | B10: 1.5472541e-07 | C10: 0.76798645 | D10: 59.986602 | E10: 0 | F10: =E10/60 -> 0 | G10: =F10*B10 -> 0 | H10: =17.285*G10^0.664 -> 0 | J10: 44781.074 | K10: 2.0470761e-06 | L10: 1.4280256 | M10: 61.699658 | N10: 0 | O10: =N10/60 -> 0 | P10: =O10*K10 -> 0 | Q10: =17.285*P10^0.664 -> 0 | S10: 45136.073 | T10: 0.00095839376 | U10: 0.85462156 | V10: 63.394821 | W10: 1437 | X10: =W10/60 -> 23.95 | Y10: =T10*X10 -> 0.022953531 | Z10: =17.285*Y10^0.664 -> 1.4101764 | AB10: 45151.073 | AC10: 0.00069311786 | AD10: 62.631509 | AE10: 536 | AF10: =AE10/60 -> 8.9333333 | AG10: =AF10*AC10 -> 0.0061918529 | AH10: =17.285*AG10^0.664 -> 0.590797 | AJ10: 45166.073 | AK10: 0.0014561838 | AL10: 62.597895 | AM10: 3199 | AN10: =AM10/60 -> 53.316667 | AO10: =AN10*AK10 -> 0.077638867 | AP10: =17.285*AO10^0.664 -> 3.1672472 | AR10: 45183.073 | AS10: 0.0007909598 | AT10: 0.50323378 | AU10: 63.505989 | AV10: 1047 | AW10: =AV10/60 -> 17.45 | AX10: =AW10*AS10 -> 0.013802249 | AY10: =17.285*AX10^0.664 -> 1.0059956 | BA10: 45030.792 | BB10: 0.0052685549 | BC10: 62.304573 | BD10: 107.28 | BE10: 40666 | BF10: =BE10/60 -> 677.76667 | BG10: =BF10*BB10 -> 3.5708509 | BH10: =17.285*BG10^0.664 -> 40.244803
A11: 44776.084 | B11: 1.4647854e-07 | C11: 0.75639067 | D11: 60.092663 | E11: 0 | F11: =E11/60 -> 0 | G11: =F11*B11 -> 0 | H11: =17.285*G11^0.664 -> 0 | J11: 44781.084 | K11: 2.1514884e-06 | L11: 1.4664621 | M11: 61.635431 | N11: 0 | O11: =N11/60 -> 0 | P11: =O11*K11 -> 0 | Q11: =17.285*P11^0.664 -> 0 | S11: 45136.083 | T11: 0.0014958581 | U11: 1.25751 | V11: 63.556461 | W11: 6938 | X11: =W11/60 -> 115.63333 | Y11: =T11*X11 -> 0.17297106 | Z11: =17.285*Y11^0.664 -> 5.391179 | AB11: 45151.083 | AC11: 0.00079991122 | AD11: 62.63066 | AE11: 889 | AF11: =AE11/60 -> 14.816667 | AG11: =AF11*AC11 -> 0.011852018 | AH11: =17.285*AG11^0.664 -> 0.90921684 | AJ11: 45166.083 | AK11: 0.0014940498 | AL11: 62.677522 | AM11: 2887 | AN11: =AM11/60 -> 48.116667 | AO11: =AN11*AK11 -> 0.071888694 | AP11: =17.285*AO11^0.664 -> 3.0094839 | AR11: 45183.083 | AS11: 0.0010747995 | AT11: 0.50323378 | AU11: 63.546033 | AV11: 1086 | AW11: =AV11/60 -> 18.1 | AX11: =AW11*AS11 -> 0.019453871 | AY11: =17.285*AX11^0.664 -> 1.2634829 | BA11: 45030.802 | BB11: 0.0049718075 | BC11: 57.147662 | BD11: 107.4 | BE11: 40670 | BF11: =BE11/60 -> 677.83333 | BG11: =BF11*BB11 -> 3.3700569 | BH11: =17.285*BG11^0.664 -> 38.727593
A12: 44776.094 | B12: 1.250865e-07 | C12: 0.72541048 | D12: 60.295657 | E12: 0 | F12: =E12/60 -> 0 | G12: =F12*B12 -> 0 | H12: =17.285*G12^0.664 -> 0 | J12: 44781.094 | K12: 1.8184881e-06 | L12: 1.3805518 | M12: 61.635431 | N12: 0 | O12: =N12/60 -> 0 | P12: =O12*K12 -> 0 | Q12: =17.285*P12^0.664 -> 0 | S12: 45136.094 | T12: 0.00086581232 | U12: 0.85462156 | V12: 63.664412 | W12: 1396 | X12: =W12/60 -> 23.266667 | Y12: =T12*X12 -> 0.020144567 | Z12: =17.285*Y12^0.664 -> 1.2930945 | AB12: 45151.094 | AC12: 0.00062058069 | AD12: 62.63066 | AE12: 403 | AF12: =AE12/60 -> 6.7166667 | AG12: =AF12*AC12 -> 0.0041682336 | AH12: =17.285*AG12^0.664 -> 0.45427365 | AJ12: 45166.094 | AK12: 0.0011731561 | AL12: 62.677522 | AM12: 1655 | AN12: =AM12/60 -> 27.583333 | AO12: =AN12*AK12 -> 0.032359556 | AP12: =17.285*AO12^0.664 -> 1.7713773 | AR12: 45183.094 | AS12: 0.00084543114 | AT12: 0.50323378 | AU12: 63.586077 | AV12: 1092 | AW12: =AV12/60 -> 18.2 | AX12: =AW12*AS12 -> 0.015386847 | AY12: =17.285*AX12^0.664 -> 1.0812764 | BA12: 45030.812 | BB12: 0.004791518 | BC12: 58.466045 | BD12: 107.4 | BE12: 40623 | BF12: =BE12/60 -> 677.05 | BG12: =BF12*BB12 -> 3.2440973 | BH12: =17.285*BG12^0.664 -> 37.760324
A13: 44776.105 | B13: 1.5005888e-07 | C13: 0.74867457 | D13: 60.405231 | E13: 0 | F13: =E13/60 -> 0 | G13: =F13*B13 -> 0 | H13: =17.285*G13^0.664 -> 0 | J13: 44781.105 | K13: 1.47054e-06 | L13: 1.3215777 | M13: 61.597976 | N13: 0 | O13: =N13/60 -> 0 | P13: =O13*K13 -> 0 | Q13: =17.285*P13^0.664 -> 0 | S13: 45136.104 | T13: 0.0010524582 | U13: 0.99067577 | V13: 63.664412 | W13: 2451 | X13: =W13/60 -> 40.85 | Y13: =T13*X13 -> 0.042992919 | Z13: =17.285*Y13^0.664 -> 2.1391683 | AB13: 45151.104 | AC13: 0.00085031722 | AD13: 62.63066 | AE13: 940 | AF13: =AE13/60 -> 15.666667 | AG13: =AF13*AC13 -> 0.013321636 | AH13: =17.285*AG13^0.664 -> 0.98259741 | AJ13: 45166.104 | AK13: 0.0010847456 | AL13: 62.677522 | AM13: 1766 | AN13: =AM13/60 -> 29.433333 | AO13: =AN13*AK13 -> 0.031927679 | AP13: =17.285*AO13^0.664 -> 1.7556442 | AR13: 45183.104 | AS13: 0.00087835159 | AT13: 0.53201108 | AU13: 63.586077 | AV13: 1142 | AW13: =AV13/60 -> 19.033333 | AX13: =AW13*AS13 -> 0.016717959 | AY13: =17.285*AX13^0.664 -> 1.142518 | BA13: 45030.823 | BB13: 0.0051991461 | BC13: 62.304573 | BD13: 107.4 | BE13: 41391 | BF13: =BE13/60 -> 689.85 | BG13: =BF13*BB13 -> 3.586631 | BH13: =17.285*BG13^0.664 -> 40.362806
A14: 44776.115 | B14: 1.4259904e-07 | C14: 0.77382161 | D14: 60.461449 | E14: 0 | F14: =E14/60 -> 0 | G14: =F14*B14 -> 0 | H14: =17.285*G14^0.664 -> 0 | J14: 44781.115 | K14: 1.5936219e-06 | L14: 1.3305822 | M14: 61.538608 | N14: 0 | O14: =N14/60 -> 0 | P14: =O14*K14 -> 0 | Q14: =17.285*P14^0.664 -> 0 | S14: 45136.115 | T14: 0.0011752928 | U14: 0.99067577 | V14: 63.825373 | W14: 2475 | X14: =W14/60 -> 41.25 | Y14: =T14*X14 -> 0.048480828 | Z14: =17.285*Y14^0.664 -> 2.3167965 | AB14: 45151.115 | AC14: 0.00090879076 | AD14: 62.63066 | AE14: 783 | AF14: =AE14/60 -> 13.05 | AG14: =AF14*AC14 -> 0.011859719 | AH14: =17.285*AG14^0.664 -> 0.9096091 | AJ14: 45166.115 | AK14: 0.0012825273 | AL14: 62.677522 | AM14: 1730 | AN14: =AM14/60 -> 28.833333 | AO14: =AN14*AK14 -> 0.036979537 | AP14: =17.285*AO14^0.664 -> 1.9355117 | AR14: 45183.115 | AS14: 0.00094365743 | AT14: 0.50323378 | AU14: 63.586077 | AV14: 1050 | AW14: =AV14/60 -> 17.5 | AX14: =AW14*AS14 -> 0.016514005 | AY14: =17.285*AX14^0.664 -> 1.1332439 | BA14: 45030.833 | BB14: 0.0054892908 | BC14: 64.455597 | BD14: 107.4 | BE14: 40893 | BF14: =BE14/60 -> 681.55 | BG14: =BF14*BB14 -> 3.7412262 | BH14: =17.285*BG14^0.664 -> 41.509801
... A22: 44776.199 | B22: 1.2609226e-07 | C22: 0.7384562 | D22: 60.709773 | E22: 0 | F22: =E22/60 -> 0 | G22: =F22*B22 -> 0 | H22: =17.285*G22^0.664 -> 0 | J22: 44781.199 | K22: 1.5411817e-06 | L22: 1.372761 | M22: 61.422755 | N22: 0 | O22: =N22/60 -> 0 | P22: =O22*K22 -> 0 | Q22: =17.285*P22^0.664 -> 0 | S22: 45136.198 | T22: 0.00083633058 | U22: 0.85462156 | V22: 63.502772 | W22: 1248 | X22: =W22/60 -> 20.8 | Y22: =T22*X22 -> 0.017395676 | Z22: =17.285*Y22^0.664 -> 1.1730659 | AB22: 45151.198 | AC22: 0.00081677553 | AD22: 62.634924 | AE22: 599 | AF22: =AE22/60 -> 9.9833333 | AG22: =AF22*AC22 -> 0.0081541424 | AH22: =17.285*AG22^0.664 -> 0.7092912 | AJ22: 45166.198 | AK22: 0.0014028943 | AL22: 62.575707 | AM22: 2136 | AN22: =AM22/60 -> 35.6 | AO22: =AN22*AK22 -> 0.049943036 | AP22: =17.285*AO22^0.664 -> 2.362962 | AR22: 45183.198 | AS22: 0.00091208684 | AT22: 0.50323378 | AU22: 63.805426 | AV22: 996 | AW22: =AV22/60 -> 16.6 | AX22: =AW22*AS22 -> 0.015140642 | AY22: =17.285*AX22^0.664 -> 1.0697571 | BA22: 45030.917 | BB22: 0.0045812784 | BC22: 59.125991 | BD22: 106.94 | BE22: 40706 | BF22: =BE22/60 -> 678.43333 | BG22: =BF22*BB22 -> 3.108092 | BH22: =17.285*BG22^0.664 -> 36.701626
A23: 44776.209 | B23: 1.2059264e-07 | C23: 0.72657533 | D23: 60.745694 | E23: 0 | F23: =E23/60 -> 0 | G23: =F23*B23 -> 0 | H23: =17.285*G23^0.664 -> 0 | J23: 44781.209 | K23: 1.4084254e-06 | L23: 1.3106306 | M23: 61.422755 | N23: 0 | O23: =N23/60 -> 0 | P23: =O23*K23 -> 0 | Q23: =17.285*P23^0.664 -> 0 | S23: 45136.208 | T23: 0.0010761126 | U23: 0.99067577 | V23: 63.664412 | W23: 2613 | X23: =W23/60 -> 43.55 | Y23: =T23*X23 -> 0.046864704 | Z23: =17.285*Y23^0.664 -> 2.2652234 | AB23: 45151.208 | AC23: 0.00065505439 | AD23: 62.634924 | AE23: 580 | AF23: =AE23/60 -> 9.6666667 | AG23: =AF23*AC23 -> 0.0063321924 | AH23: =17.285*AG23^0.664 -> 0.59965479 | AJ23: 45166.208 | AK23: 0.0011952932 | AL23: 62.575707 | AM23: 2167 | AN23: =AM23/60 -> 36.116667 | AO23: =AN23*AK23 -> 0.043170004 | AP23: =17.285*AO23^0.664 -> 2.1450148 | AR23: 45183.208 | AS23: 0.0014183005 | AT23: 0.59425535 | AU23: 63.809388 | AV23: 1380 | AW23: =AV23/60 -> 23 | AX23: =AW23*AS23 -> 0.032620911 | AY23: =17.285*AX23^0.664 -> 1.7808641 | BA23: 45030.927 | BB23: 0.0046121355 | BC23: 59.769842 | BD23: 106.91 | BE23: 40409 | BF23: =BE23/60 -> 673.48333 | BG23: =BF23*BB23 -> 3.1061964 | BH23: =17.285*BG23^0.664 -> 36.686762 | BJ23: 1) | BK23: Interpolated Rising D50 | BO23: 2) | BP23: Interpolated Rising D84
A24: 44776.219 | B24: 1.4862872e-07 | C24: 0.78202204 | D24: 60.745694 | E24: 0 | F24: =E24/60 -> 0 | G24: =F24*B24 -> 0 | H24: =17.285*G24^0.664 -> 0 | J24: 44781.219 | K24: 1.5660833e-06 | L24: 1.3304172 | M24: 61.422755 | N24: 0 | O24: =N24/60 -> 0 | P24: =O24*K24 -> 0 | Q24: =17.285*P24^0.664 -> 0 | S24: 45136.219 | T24: 0.0012299296 | U24: 0.99067577 | V24: 63.814924 | W24: 3203 | X24: =W24/60 -> 53.383333 | Y24: =T24*X24 -> 0.065657744 | Z24: =17.285*Y24^0.664 -> 2.8336569 | AB24: 45151.219 | AC24: 0.001034203 | AD24: 62.634924 | AE24: 1089 | AF24: =AE24/60 -> 18.15 | AG24: =AF24*AC24 -> 0.018770785 | AH24: =17.285*AG24^0.664 -> 1.2338482 | AJ24: 45166.219 | AK24: 0.0017143408 | AL24: 62.575707 | AM24: 3053 | AN24: =AM24/60 -> 50.883333 | AO24: =AN24*AK24 -> 0.087231376 | AP24: =17.285*AO24^0.664 -> 3.421969 | AR24: 45183.219 | AS24: 0.00079401262 | AT24: 0.44894941 | AU24: 63.809388 | AV24: 773 | AW24: =AV24/60 -> 12.883333 | AX24: =AW24*AS24 -> 0.010229529 | AY24: =17.285*AX24^0.664 -> 0.82454343 | BA24: 45030.938 | BB24: 0.0045866794 | BC24: 59.769842 | BD24: 106.9 | BE24: 40426 | BF24: =BE24/60 -> 673.76667 | BG24: =BF24*BB24 -> 3.0903517 | BH24: =17.285*BG24^0.664 -> 36.562395 | BK24: Mobile | BL24: Total | BM24: Dmax (mm) | BO24: Tau (Pa) - Total | BP24: Dmax (mm)
A25: 44776.23 | B25: 1.7464465e-07 | C25: 0.83594534 | D25: 60.745694 | E25: 0 | F25: =E25/60 -> 0 | G25: =F25*B25 -> 0 | H25: =17.285*G25^0.664 -> 0 | J25: 44781.23 | K25: 1.1204099e-06 | L25: 1.2636095 | M25: 61.355468 | N25: 0 | O25: =N25/60 -> 0 | P25: =O25*K25 -> 0 | Q25: =17.285*P25^0.664 -> 0 | S25: 45136.229 | T25: 0.00083504883 | U25: 0.89783228 | V25: 63.975884 | W25: 1412 | X25: =W25/60 -> 23.533333 | Y25: =T25*X25 -> 0.019651482 | Z25: =17.285*Y25^0.664 -> 1.2719905 | AB25: 45151.229 | AC25: 0.00056545265 | AD25: 62.663283 | AE25: 352 | AF25: =AE25/60 -> 5.8666667 | AG25: =AF25*AC25 -> 0.0033173222 | AH25: =17.285*AG25^0.664 -> 0.39036636 | AJ25: 45166.229 | AK25: 0.0017697915 | AL25: 62.575707 | AM25: 3619 | AN25: =AM25/60 -> 60.316667 | AO25: =AN25*AK25 -> 0.10674792 | AP25: =17.285*AO25^0.664 -> 3.9129117 | AR25: 45183.229 | AS25: 0.0015045671 | AT25: 0.66228852 | AU25: 63.809388 | AV25: 1727 | AW25: =AV25/60 -> 28.783333 | AX25: =AW25*AS25 -> 0.043306456 | AY25: =17.285*AX25^0.664 -> 2.1495143 | BA25: 45030.948 | BB25: 0.0046532578 | BC25: 55.826368 | BD25: 106.86 | BE25: 41006 | BF25: =BE25/60 -> 683.43333 | BG25: =BF25*BB25 -> 3.1801915 | BH25: =17.285*BG25^0.664 -> 37.264762 | BJ25: =BA84 -> 45031.562 | BK25: =BC84 -> 50.381721 | BL25: =BD84 -> 100.58 | BM25: =BH84 -> 32.224765 | BN25: =BA1096 -> 45044.115 | BO25: =BD1096 -> 114.76 | BP25: =BH1096 -> 43.626323
A26: 44776.24 | B26: 1.4938452e-07 | C26: 0.78025977 | D26: 60.745694 | E26: 0 | F26: =E26/60 -> 0 | G26: =F26*B26 -> 0 | H26: =17.285*G26^0.664 -> 0 | J26: 44781.24 | K26: 1.2126402e-06 | L26: 1.2698033 | M26: 61.345856 | N26: 0 | O26: =N26/60 -> 0 | P26: =O26*K26 -> 0 | Q26: =17.285*P26^0.664 -> 0 | S26: 45136.24 | T26: 0.0011897177 | U26: 0.99067577 | V26: 63.986333 | W26: 2119 | X26: =W26/60 -> 35.316667 | Y26: =T26*X26 -> 0.042016863 | Z26: =17.285*Y26^0.664 -> 2.1067969 | AB26: 45151.24 | AC26: 0.00088417937 | AD26: 62.663283 | AE26: 764 | AF26: =AE26/60 -> 12.733333 | AG26: =AF26*AC26 -> 0.011258551 | AH26: =17.285*AG26^0.664 -> 0.87872656 | AJ26: 45166.24 | AK26: 0.0013615986 | AL26: 62.575707 | AM26: 2585 | AN26: =AM26/60 -> 43.083333 | AO26: =AN26*AK26 -> 0.058662205 | AP26: =17.285*AO26^0.664 -> 2.6294163 | AR26: 45183.24 | AS26: 0.00080832372 | AT26: 0.44894941 | AU26: 63.809388 | AV26: 781 | AW26: =AV26/60 -> 13.016667 | AX26: =AW26*AS26 -> 0.01052168 | AY26: =17.285*AX26^0.664 -> 0.84010563 | BA26: 45030.958 | BB26: 0.0048216498 | BC26: 59.114847 | BD26: 106.78 | BE26: 40757 | BF26: =BE26/60 -> 679.28333 | BG26: =BF26*BB26 -> 3.2752663 | BH26: =17.285*BG26^0.664 -> 38.000835 | BJ26: =BA85 -> 45031.573 | BK26: =BC85 -> 50.381721 | BL26: =BD85 -> 100.69 | BM26: =BH85 -> 61.986877 | BN26: =BA1097 -> 45044.125 | BO26: =BD1097 -> 114.76 | BP26: =BH1097 -> 101.10537
A27: 44776.251 | B27: 1.3160716e-07 | C27: 0.75657463 | D27: 60.854855 | E27: 0 | F27: =E27/60 -> 0 | G27: =F27*B27 -> 0 | H27: =17.285*G27^0.664 -> 0 | J27: 44781.251 | K27: 1.390921e-06 | L27: 1.3586244 | M27: 61.345185 | N27: 0 | O27: =N27/60 -> 0 | P27: =O27*K27 -> 0 | Q27: =17.285*P27^0.664 -> 0 | S27: 45136.25 | T27: 0.0017589253 | U27: 1.1441743 | V27: 63.986333 | W27: 4577 | X27: =W27/60 -> 76.283333 | Y27: =T27*X27 -> 0.13417668 | Z27: =17.285*Y27^0.664 -> 4.5545654 | AB27: 45151.25 | AC27: 0.0010249092 | AD27: 62.763401 | AE27: 872 | AF27: =AE27/60 -> 14.533333 | AG27: =AF27*AC27 -> 0.014895347 | AH27: =17.285*AG27^0.664 -> 1.0582177 | AJ27: 45166.25 | AK27: 0.0012843127 | AL27: 62.575707 | AM27: 1673 | AN27: =AM27/60 -> 27.883333 | AO27: =AN27*AK27 -> 0.035810921 | AP27: =17.285*AO27^0.664 -> 1.8946791 | AR27: 45183.25 | AS27: 0.00094275985 | AT27: 0.59425535 | AU27: 63.809388 | AV27: 1471 | AW27: =AV27/60 -> 24.516667 | AX27: =AW27*AS27 -> 0.023113329 | AY27: =17.285*AX27^0.664 -> 1.4166876 | BA27: 45030.969 | BB27: 0.0048162962 | BC27: 61.042519 | BD27: 106.64 | BE27: 40466 | BF27: =BE27/60 -> 674.43333 | BG27: =BF27*BB27 -> 3.2482707 | BH27: =17.285*BG27^0.664 -> 37.792572 | BJ27: =_xlfn.FORECAST.LINEAR(BM27,BJ25:BJ26,BM25:BM26) -> 45031.566 | BK27: =_xlfn.FORECAST.LINEAR(BM27,BK25:BK26,BM25:BM26) -> 50.381721 | BL27: =_xlfn.FORECAST.LINEAR(BM27,BL25:BL26,BM25:BM26) -> 100.62219 | BM27: 43.64 | BN27: =_xlfn.FORECAST.LINEAR(BP27,BN25:BN26,BP25:BP26) -> 45044.122 | BO27: =_xlfn.FORECAST.LINEAR(BP27,BO25:BO26,BP25:BP26) -> 114.76 | BP27: 82
A28: 44776.261 | B28: 9.909021e-08 | C28: 0.70298291 | D28: 60.854855 | E28: 0 | F28: =E28/60 -> 0 | G28: =F28*B28 -> 0 | H28: =17.285*G28^0.664 -> 0 | J28: 44781.261 | K28: 1.3257395e-06 | L28: 1.3056303 | M28: 61.294172 | N28: 0 | O28: =N28/60 -> 0 | P28: =O28*K28 -> 0 | Q28: =17.285*P28^0.664 -> 0 | S28: 45136.26 | T28: 0.0010541572 | U28: 0.89783228 | V28: 64.039697 | W28: 1330 | X28: =W28/60 -> 22.166667 | Y28: =T28*X28 -> 0.023367152 | Z28: =17.285*Y28^0.664 -> 1.4269988 | AB28: 45151.26 | AC28: 0.00078612044 | AD28: 62.763401 | AE28: 904 | AF28: =AE28/60 -> 15.066667 | AG28: =AF28*AC28 -> 0.011844215 | AH28: =17.285*AG28^0.664 -> 0.90881931 | AJ28: 45166.26 | AK28: 0.00089163845 | AL28: 62.575707 | AM28: 1302 | AN28: =AM28/60 -> 21.7 | AO28: =AN28*AK28 -> 0.019348554 | AP28: =17.285*AO28^0.664 -> 1.258937 | AR28: 45183.26 | AS28: 0.00097778815 | AT28: 0.44894941 | AU28: 63.809388 | AV28: 736 | AW28: =AV28/60 -> 12.266667 | AX28: =AW28*AS28 -> 0.011994201 | AY28: =17.285*AX28^0.664 -> 0.91644488 | BA28: 45030.979 | BB28: 0.0046209837 | BC28: 57.814718 | BD28: 106.64 | BE28: 39733 | BF28: =BE28/60 -> 662.21667 | BG28: =BF28*BB28 -> 3.0600924 | BH28: =17.285*BG28^0.664 -> 36.324289 | BJ28: Dimensionless | BK28: =BK27/(1650*9.81*0.04364) -> 0.071323936 | BL28: =BL27/(1650*9.81*0.04364) -> 0.14244791
A29: 44776.272 | B29: 8.8754464e-08 | C29: 0.68254178 | D29: 60.969214 | E29: 0 | F29: =E29/60 -> 0 | G29: =F29*B29 -> 0 | H29: =17.285*G29^0.664 -> 0 | J29: 44781.272 | K29: 1.1430224e-06 | L29: 1.2676346 | M29: 61.218901 | N29: 0 | O29: =N29/60 -> 0 | P29: =O29*K29 -> 0 | Q29: =17.285*P29^0.664 -> 0 | S29: 45136.271 | T29: 0.0013472828 | U29: 1.1441743 | V29: 64.191238 | W29: 3318 | X29: =W29/60 -> 55.3 | Y29: =T29*X29 -> 0.07450474 | Z29: =17.285*Y29^0.664 -> 3.0817648 | AB29: 45151.271 | AC29: 0.0011346058 | AD29: 62.763401 | AE29: 1221 | AF29: =AE29/60 -> 20.35 | AG29: =AF29*AC29 -> 0.023089228 | AH29: =17.285*AG29^0.664 -> 1.4157065 | AJ29: 45166.271 | AK29: 0.0014539313 | AL29: 62.575707 | AM29: 2307 | AN29: =AM29/60 -> 38.45 | AO29: =AN29*AK29 -> 0.05590366 | AP29: =17.285*AO29^0.664 -> 2.5466526 | AR29: 45183.271 | AS29: 0.00067519447 | AT29: 0.44939224 | AU29: 63.789517 | AV29: 746 | AW29: =AV29/60 -> 12.433333 | AX29: =AW29*AS29 -> 0.0083949179 | AY29: =17.285*AX29^0.664 -> 0.72312988 | BA29: 45030.99 | BB29: 0.0047920345 | BC29: 62.923033 | BD29: 106.64 | BE29: 40087 | BF29: =BE29/60 -> 668.11667 | BG29: =BF29*BB29 -> 3.2016381 | BH29: =17.285*BG29^0.664 -> 37.431441 | BJ29: 3) | BK29: Exceedance of D50 | BN29: 4) | BO29: Exceedance of D84
A30: 44776.282 | B30: 8.4536835e-08 | C30: 0.68446578 | D30: 60.969214 | E30: 0 | F30: =E30/60 -> 0 | G30: =F30*B30 -> 0 | H30: =17.285*G30^0.664 -> 0 | J30: 44781.282 | K30: 1.0727191e-06 | L30: 1.2868848 | M30: 61.196166 | N30: 0 | O30: =N30/60 -> 0 | P30: =O30*K30 -> 0 | Q30: =17.285*P30^0.664 -> 0 | S30: 45136.281 | T30: 0.00066291889 | U30: 0.73432994 | V30: 64.191238 | W30: 555 | X30: =W30/60 -> 9.25 | Y30: =T30*X30 -> 0.0061319997 | Z30: =17.285*Y30^0.664 -> 0.58699878 | AB30: 45151.281 | AC30: 0.0010815771 | AD30: 62.763401 | AE30: 745 | AF30: =AE30/60 -> 12.416667 | AG30: =AF30*AC30 -> 0.013429583 | AH30: =17.285*AG30^0.664 -> 0.98787705 | AJ30: 45166.281 | AK30: 0.0012781236 | AL30: 62.575707 | AM30: 2168 | AN30: =AM30/60 -> 36.133333 | AO30: =AN30*AK30 -> 0.046182865 | AP30: =17.285*AO30^0.664 -> 2.2432862 | AR30: 45183.281 | AS30: 0.0010142412 | AT30: 0.44939224 | AU30: 63.789517 | AV30: 747 | AW30: =AV30/60 -> 12.45 | AX30: =AW30*AS30 -> 0.012627303 | AY30: =17.285*AX30^0.664 -> 0.94828663 | BA30: 45031 | BB30: 0.0043983269 | BC30: 57.814718 | BD30: 106.64 | BE30: 40282 | BF30: =BE30/60 -> 671.36667 | BG30: =BF30*BB30 -> 2.9528901 | BH30: =17.285*BG30^0.664 -> 35.474279 | BK30: Mobile | BL30: Total | BM30: Dmax (mm) | BO30: Tau (Pa) | BP30: Dmax (mm)
A31: 44776.292 | B31: 9.3792592e-08 | C31: 0.69437549 | D31: 60.969214 | E31: 0 | F31: =E31/60 -> 0 | G31: =F31*B31 -> 0 | H31: =17.285*G31^0.664 -> 0 | J31: 44781.292 | K31: 1.2840633e-06 | L31: 1.2461574 | M31: 61.196166 | N31: 0 | O31: =N31/60 -> 0 | P31: =O31*K31 -> 0 | Q31: =17.285*P31^0.664 -> 0 | S31: 45136.292 | T31: 0.0009498373 | U31: 0.85462156 | V31: 64.039697 | W31: 1189 | X31: =W31/60 -> 19.816667 | Y31: =T31*X31 -> 0.018822609 | Z31: =17.285*Y31^0.664 -> 1.2361091 | AB31: 45151.292 | AC31: 0.00072623662 | AD31: 62.763401 | AE31: 562 | AF31: =AE31/60 -> 9.3666667 | AG31: =AF31*AC31 -> 0.0068024163 | AH31: =17.285*AG31^0.664 -> 0.62886548 | AJ31: 45166.292 | AK31: 0.0011975768 | AL31: 62.575707 | AM31: 1234 | AN31: =AM31/60 -> 20.566667 | AO31: =AN31*AK31 -> 0.024630163 | AP31: =17.285*AO31^0.664 -> 1.4777592 | AR31: 45183.292 | AS31: 0.00066072808 | AT31: 0.44939224 | AU31: 63.762872 | AV31: 849 | AW31: =AV31/60 -> 14.15 | AX31: =AW31*AS31 -> 0.0093493023 | AY31: =17.285*AX31^0.664 -> 0.77672409 | BA31: 45031.01 | BB31: 0.0048020942 | BC31: 61.042519 | BD31: 106.5 | BE31: 40718 | BF31: =BE31/60 -> 678.63333 | BG31: =BF31*BB31 -> 3.2588612 | BH31: =17.285*BG31^0.664 -> 37.874344 | BJ31: =BJ26 -> 45031.573 | BK31: =BK26 -> 50.381721 | BL31: =BL26 -> 100.69 | BM31: =BM26 -> 61.986877 | BN31: =BN26 -> 45044.125 | BO31: =BO26 -> 114.76 | BP31: =BP26 -> 101.10537
A32: 44776.303 | B32: 1.1000501e-07 | C32: 0.70371788 | D32: 60.842748 | E32: 0 | F32: =E32/60 -> 0 | G32: =F32*B32 -> 0 | H32: =17.285*G32^0.664 -> 0 | J32: 44781.303 | K32: 1.0805789e-06 | L32: 1.2263406 | M32: 61.176041 | N32: 0 | O32: =N32/60 -> 0 | P32: =O32*K32 -> 0 | Q32: =17.285*P32^0.664 -> 0 | S32: 45136.302 | T32: 0.0017754666 | U32: 1.1451054 | V32: 64.029248 | W32: 5417 | X32: =W32/60 -> 90.283333 | Y32: =T32*X32 -> 0.16029504 | Z32: =17.285*Y32^0.664 -> 5.125501 | AB32: 45151.302 | AC32: 0.0012149695 | AD32: 62.763401 | AE32: 675 | AF32: =AE32/60 -> 11.25 | AG32: =AF32*AC32 -> 0.013668407 | AH32: =17.285*AG32^0.664 -> 0.99950753 | AJ32: 45166.302 | AK32: 0.00097787795 | AL32: 62.575707 | AM32: 1017 | AN32: =AM32/60 -> 16.95 | AO32: =AN32*AK32 -> 0.016575031 | AP32: =17.285*AO32^0.664 -> 1.1360229 | AR32: 45183.302 | AS32: 0.00073770413 | AT32: 0.44894941 | AU32: 63.716355 | AV32: 749 | AW32: =AV32/60 -> 12.483333 | AX32: =AW32*AS32 -> 0.0092090066 | AY32: =17.285*AX32^0.664 -> 0.76896518 | BA32: 45031.021 | BB32: 0.0045219532 | BC32: 57.147662 | BD32: 106.56 | BE32: 40480 | BF32: =BE32/60 -> 674.66667 | BG32: =BF32*BB32 -> 3.0508111 | BH32: =17.285*BG32^0.664 -> 36.251097 | BJ32: Dimensionless | BK32: =BK31/(1650*9.81*0.04364) -> 0.071323936 | BL32: =BL31/(1650*9.81*0.04364) -> 0.1425439
A33: 44776.313 | B33: 7.4226951e-08 | C33: 0.67222234 | D33: 60.842748 | E33: 0 | F33: =E33/60 -> 0 | G33: =F33*B33 -> 0 | H33: =17.285*G33^0.664 -> 0 | J33: 44781.313 | K33: 1.1052765e-06 | L33: 1.2605418 | M33: 61.152868 | N33: 0 | O33: =N33/60 -> 0 | P33: =O33*K33 -> 0 | Q33: =17.285*P33^0.664 -> 0 | S33: 45136.312 | T33: 0.0019469639 | U33: 1.25751 | V33: 65.355783 | W33: 7208 | X33: =W33/60 -> 120.13333 | Y33: =T33*X33 -> 0.23389526 | Z33: =17.285*Y33^0.664 -> 6.5871812 | AB33: 45151.312 | AC33: 0.00067911512 | AD33: 62.763401 | AE33: 572 | AF33: =AE33/60 -> 9.5333333 | AG33: =AF33*AC33 -> 0.0064742309 | AH33: =17.285*AG33^0.664 -> 0.6085529 | AJ33: 45166.312 | AK33: 0.0015378851 | AL33: 62.575707 | AM33: 1674 | AN33: =AM33/60 -> 27.9 | AO33: =AN33*AK33 -> 0.042906996 | AP33: =17.285*AO33^0.664 -> 2.1363286 | AR33: 45183.312 | AS33: 0.00080601342 | AT33: 0.53201108 | AU33: 63.716355 | AV33: 1150 | AW33: =AV33/60 -> 19.166667 | AX33: =AW33*AS33 -> 0.015448591 | AY33: =17.285*AX33^0.664 -> 1.0841555 | BA33: 45031.031 | BB33: 0.0051044142 | BC33: 61.042519 | BD33: 106.5 | BE33: 40121 | BF33: =BE33/60 -> 668.68333 | BG33: =BF33*BB33 -> 3.4132367 | BH33: =17.285*BG33^0.664 -> 39.05637 | BJ33: 5) | BK33: Interpolated Falling D50 | BN33: 6) | BO33: Interpolated Falling D84
A34: 44776.324 | B34: 8.3748998e-08 | C34: 0.67980481 | D34: 60.701772 | E34: 0 | F34: =E34/60 -> 0 | G34: =F34*B34 -> 0 | H34: =17.285*G34^0.664 -> 0 | J34: 44781.324 | K34: 1.2197556e-06 | L34: 1.2897381 | M34: 61.14907 | N34: 0 | O34: =N34/60 -> 0 | P34: =O34*K34 -> 0 | Q34: =17.285*P34^0.664 -> 0 | S34: 45136.323 | T34: 0.0017795606 | U34: 1.1451054 | V34: 64.029248 | W34: 5096 | X34: =W34/60 -> 84.933333 | Y34: =T34*X34 -> 0.15114402 | Z34: =17.285*Y34^0.664 -> 4.9292969 | AB34: 45151.323 | AC34: 0.00039799223 | AD34: 62.763401 | AE34: 181 | AF34: =AE34/60 -> 3.0166667 | AG34: =AF34*AC34 -> 0.0012006099 | AH34: =17.285*AG34^0.664 -> 0.19878896 | AJ34: 45166.323 | AK34: 0.0020212901 | AL34: 62.523627 | AM34: 3733 | AN34: =AM34/60 -> 62.216667 | AO34: =AN34*AK34 -> 0.12575793 | AP34: =17.285*AO34^0.664 -> 4.3627556 | AR34: 45183.323 | AS34: 0.00084813302 | AT34: 0.44894941 | AU34: 63.713332 | AV34: 741 | AW34: =AV34/60 -> 12.35 | AX34: =AW34*AS34 -> 0.010474443 | AY34: =17.285*AX34^0.664 -> 0.83759933 | BA34: 45031.042 | BB34: 0.0043919286 | BC34: 59.114847 | BD34: 106.41 | BE34: 40409 | BF34: =BE34/60 -> 673.48333 | BG34: =BF34*BB34 -> 2.9578907 | BH34: =17.285*BG34^0.664 -> 35.514157 | BK34: Mobile | BL34: Total | BM34: Dmax (mm) | BO34: Tau (Pa) | BP34: Dmax (mm)
A35: 44776.334 | B35: 1.3456036e-07 | C35: 0.74230588 | D35: 60.648935 | E35: 0 | F35: =E35/60 -> 0 | G35: =F35*B35 -> 0 | H35: =17.285*G35^0.664 -> 0 | J35: 44781.334 | K35: 1.4116176e-06 | L35: 1.3268671 | M35: 61.147546 | N35: 0 | O35: =N35/60 -> 0 | P35: =O35*K35 -> 0 | Q35: =17.285*P35^0.664 -> 0 | S35: 45136.333 | T35: 0.0017898928 | U35: 1.318149 | V35: 65.426284 | W35: 7929 | X35: =W35/60 -> 132.15 | Y35: =T35*X35 -> 0.23653434 | Z35: =17.285*Y35^0.664 -> 6.6364393 | AB35: 45151.333 | AC35: 0.00058364466 | AD35: 62.763401 | AE35: 350 | AF35: =AE35/60 -> 5.8333333 | AG35: =AF35*AC35 -> 0.0034045938 | AH35: =17.285*AG35^0.664 -> 0.39715565 | AJ35: 45166.333 | AK35: 0.0013750393 | AL35: 62.453146 | AM35: 2443 | AN35: =AM35/60 -> 40.716667 | AO35: =AN35*AK35 -> 0.055987017 | AP35: =17.285*AO35^0.664 -> 2.5491733 | AR35: 45183.333 | AS35: 0.00076798649 | AT35: 0.39953382 | AU35: 63.644466 | AV35: 520 | AW35: =AV35/60 -> 8.6666667 | AX35: =AW35*AS35 -> 0.0066558829 | AY35: =17.285*AX35^0.664 -> 0.61983765 | BA35: 45031.052 | BB35: 0.0045664849 | BC35: 59.769842 | BD35: 106.36 | BE35: 40576 | BF35: =BE35/60 -> 676.26667 | BG35: =BF35*BB35 -> 3.0881615 | BH35: =17.285*BG35^0.664 -> 36.545187 | BJ35: =BA1387 -> 45047.146 | BK35: =BC1387 -> 81.405229 | BL35: =BD1387 -> 117.83 | BM35: =BH1387 -> 42.519582 | BN35: 45044.115 | BO35: 114.76 | BP35: 43.626323
A36: 44776.344 | B36: 1.3044574e-07 | C36: 0.76352864 | D36: 60.648935 | E36: 0 | F36: =E36/60 -> 0 | G36: =F36*B36 -> 0 | H36: =17.285*G36^0.664 -> 0 | J36: 44781.344 | K36: 1.4505692e-06 | L36: 1.314942 | M36: 61.135042 | N36: 0 | O36: =N36/60 -> 0 | P36: =O36*K36 -> 0 | Q36: =17.285*P36^0.664 -> 0 | S36: 45136.344 | T36: 0.0018486334 | U36: 1.318149 | V36: 65.104038 | W36: 9329 | X36: =W36/60 -> 155.48333 | Y36: =T36*X36 -> 0.28743168 | Z36: =17.285*Y36^0.664 -> 7.5532938 | AB36: 45151.344 | AC36: 0.00062896729 | AD36: 62.661575 | AE36: 322 | AF36: =AE36/60 -> 5.3666667 | AG36: =AF36*AC36 -> 0.0033754578 | AH36: =17.285*AG36^0.664 -> 0.39489559 | AJ36: 45166.344 | AK36: 0.0017841165 | AL36: 62.453146 | AM36: 3339 | AN36: =AM36/60 -> 55.65 | AO36: =AN36*AK36 -> 0.099286084 | AP36: =17.285*AO36^0.664 -> 3.7290935 | AR36: 45183.344 | AS36: 0.00086038529 | AT36: 0.47522857 | AU36: 63.542306 | AV36: 910 | AW36: =AV36/60 -> 15.166667 | AX36: =AW36*AS36 -> 0.013049177 | AY36: =17.285*AX36^0.664 -> 0.96920708 | BA36: 45031.062 | BB36: 0.0048491076 | BC36: 59.769842 | BD36: 106.36 | BE36: 40160 | BF36: =BE36/60 -> 669.33333 | BG36: =BF36*BB36 -> 3.2456693 | BH36: =17.285*BG36^0.664 -> 37.772473 | BJ36: =BA1388 -> 45047.156 | BK36: =BC1388 -> 82.276893 | BL36: =BD1388 -> 117.74 | BM36: =BH1388 -> 42.762443 | BN36: 45044.125 | BO36: 114.76 | BP36: 101.10537
A37: 44776.355 | B37: 1.0828443e-07 | C37: 0.72191215 | D37: 60.627912 | E37: 0 | F37: =E37/60 -> 0 | G37: =F37*B37 -> 0 | H37: =17.285*G37^0.664 -> 0 | J37: 44781.355 | K37: 1.291379e-06 | L37: 1.3033881 | M37: 61.124117 | N37: 0 | O37: =N37/60 -> 0 | P37: =O37*K37 -> 0 | Q37: =17.285*P37^0.664 -> 0 | S37: 45136.354 | T37: 0.0014334682 | U37: 1.1451054 | V37: 63.763573 | W37: 6943 | X37: =W37/60 -> 115.71667 | Y37: =T37*X37 -> 0.16587617 | Z37: =17.285*Y37^0.664 -> 5.243315 | AB37: 45151.354 | AC37: 0.00070065378 | AD37: 62.63066 | AE37: 683 | AF37: =AE37/60 -> 11.383333 | AG37: =AF37*AC37 -> 0.0079757755 | AH37: =17.285*AG37^0.664 -> 0.6989508 | AJ37: 45166.354 | AK37: 0.0011236009 | AL37: 62.418437 | AM37: 1395 | AN37: =AM37/60 -> 23.25 | AO37: =AN37*AK37 -> 0.02612372 | AP37: =17.285*AO37^0.664 -> 1.5366701 | AR37: 45183.354 | AS37: 0.001276273 | AT37: 0.62723255 | AU37: 63.4628 | AV37: 1693 | AW37: =AV37/60 -> 28.216667 | AX37: =AW37*AS37 -> 0.036012169 | AY37: =17.285*AX37^0.664 -> 1.9017425 | BA37: 45031.073 | BB37: 0.0047128644 | BC37: 61.042519 | BD37: 106.36 | BE37: 40435 | BF37: =BE37/60 -> 673.91667 | BG37: =BF37*BB37 -> 3.1760779 | BH37: =17.285*BG37^0.664 -> 37.232749 | BJ37: =_xlfn.FORECAST.LINEAR(BM37,BJ35:BJ36,BM35:BM36) -> 45047.194 | BK37: =_xlfn.FORECAST.LINEAR(BM37,BK35:BK36,BM35:BM36) -> 85.426572 | BL37: =_xlfn.FORECAST.LINEAR(BM37,BL35:BL36,BM35:BM36) -> 117.41479 | BM37: 43.64 | BN37: =_xlfn.FORECAST.LINEAR(BP37,BN35:BN36,BP35:BP36) -> 45044.122 | BO37: =BO27 -> 114.76 | BP37: 82
A38: 44776.365 | B38: 9.84826e-08 | C38: 0.72191215 | D38: 60.543597 | E38: 0 | F38: =E38/60 -> 0 | G38: =F38*B38 -> 0 | H38: =17.285*G38^0.664 -> 0 | J38: 44781.365 | K38: 1.2035798e-06 | L38: 1.2281127 | M38: 61.103729 | N38: 0 | O38: =N38/60 -> 0 | P38: =O38*K38 -> 0 | Q38: =17.285*P38^0.664 -> 0 | S38: 45136.365 | T38: 0.0016177161 | U38: 1.1451054 | V38: 63.424423 | W38: 5718 | X38: =W38/60 -> 95.3 | Y38: =T38*X38 -> 0.15416834 | Z38: =17.285*Y38^0.664 -> 4.9945711 | AB38: 45151.365 | AC38: 0.00087318046 | AD38: 62.522348 | AE38: 721 | AF38: =AE38/60 -> 12.016667 | AG38: =AF38*AC38 -> 0.010492719 | AH38: =17.285*AG38^0.664 -> 0.83856944 | AJ38: 45166.365 | AK38: 0.0013413689 | AL38: 62.349765 | AM38: 2146 | AN38: =AM38/60 -> 35.766667 | AO38: =AN38*AK38 -> 0.047976296 | AP38: =17.285*AO38^0.664 -> 2.300759 | AR38: 45183.365 | AS38: 0.00075009988 | AT38: 0.39953382 | AU38: 63.403845 | AV38: 651 | AW38: =AV38/60 -> 10.85 | AX38: =AW38*AS38 -> 0.0081385837 | AY38: =17.285*AX38^0.664 -> 0.70839226 | BA38: 45031.083 | BB38: 0.004573587 | BC38: 65.243075 | BD38: 106.33 | BE38: 39346 | BF38: =BE38/60 -> 655.76667 | BG38: =BF38*BB38 -> 2.9992059 | BH38: =17.285*BG38^0.664 -> 35.842769 | BJ38: Dimensionless | BK38: =BK37/(1650*9.81*0.04364) -> 0.12093591 | BL38: =BL37/(1650*9.81*0.04364) -> 0.16622071
A39: 44776.376 | B39: 1.2803879e-07 | C39: 0.77710206 | D39: 60.452373 | E39: 0 | F39: =E39/60 -> 0 | G39: =F39*B39 -> 0 | H39: =17.285*G39^0.664 -> 0 | J39: 44781.376 | K39: 8.6926547e-07 | L39: 1.1599344 | M39: 61.03908 | N39: 0 | O39: =N39/60 -> 0 | P39: =O39*K39 -> 0 | Q39: =17.285*P39^0.664 -> 0 | S39: 45136.375 | T39: 0.0011741717 | U39: 0.99150227 | V39: 63.399721 | W39: 3378 | X39: =W39/60 -> 56.3 | Y39: =T39*X39 -> 0.066105867 | Z39: =17.285*Y39^0.664 -> 2.846484 | AB39: 45151.375 | AC39: 0.00096958263 | AD39: 62.414885 | AE39: 1423 | AF39: =AE39/60 -> 23.716667 | AG39: =AF39*AC39 -> 0.022995268 | AH39: =17.285*AG39^0.664 -> 1.4118785 | AJ39: 45166.375 | AK39: 0.0010361689 | AL39: 62.349765 | AM39: 1543 | AN39: =AM39/60 -> 25.716667 | AO39: =AN39*AK39 -> 0.02664681 | AP39: =17.285*AO39^0.664 -> 1.557033 | AR39: 45183.375 | AS39: 0.0005522623 | AT39: 0.39953382 | AU39: 63.337827 | AV39: 552 | AW39: =AV39/60 -> 9.2 | AX39: =AW39*AS39 -> 0.0050808132 | AY39: =17.285*AX39^0.664 -> 0.51809458 | BA39: 45031.094 | BB39: 0.004897358 | BC39: 61.053402 | BD39: 106.32 | BE39: 40215 | BF39: =BE39/60 -> 670.25 | BG39: =BF39*BB39 -> 3.2824542 | BH39: =17.285*BG39^0.664 -> 38.05619 | BJ39: 7) | BK39: Shortfall of D50 | BN39: 7) | BO39: Shortfall of D84
A40: 44776.386 | B40: 1.2629784e-07 | C40: 0.73831051 | D40: 60.437053 | E40: 0 | F40: =E40/60 -> 0 | G40: =F40*B40 -> 0 | H40: =17.285*G40^0.664 -> 0 | J40: 44781.386 | K40: 9.8526751e-07 | L40: 1.171593 | M40: 60.974058 | N40: 0 | O40: =N40/60 -> 0 | P40: =O40*K40 -> 0 | Q40: =17.285*P40^0.664 -> 0 | S40: 45136.385 | T40: 0.0015943103 | U40: 0.99150227 | V40: 63.237731 | W40: 3554 | X40: =W40/60 -> 59.233333 | Y40: =T40*X40 -> 0.094436312 | Z40: =17.285*Y40^0.664 -> 3.6071291 | AB40: 45151.385 | AC40: 0.00064802012 | AD40: 62.414885 | AE40: 396 | AF40: =AE40/60 -> 6.6 | AG40: =AF40*AC40 -> 0.0042769328 | AH40: =17.285*AG40^0.664 -> 0.46210569 | AJ40: 45166.385 | AK40: 0.0015932766 | AL40: 62.3158 | AM40: 3157 | AN40: =AM40/60 -> 52.616667 | AO40: =AN40*AK40 -> 0.083832904 | AP40: =17.285*AO40^0.664 -> 3.3328565 | AR40: 45183.385 | AS40: 0.00079036299 | AT40: 0.44894941 | AU40: 63.337827 | AV40: 735 | AW40: =AV40/60 -> 12.25 | AX40: =AW40*AS40 -> 0.0096819466 | AY40: =17.285*AX40^0.664 -> 0.79496609 | BA40: 45031.104 | BB40: 0.0041217141 | BC40: 57.814718 | BD40: 106.21 | BE40: 40449 | BF40: =BE40/60 -> 674.15 | BG40: =BF40*BB40 -> 2.7786535 | BH40: =17.285*BG40^0.664 -> 34.070258 | BK40: Mobile | BL40: Total | BM40: Dmax (mm) | BO40: Tau (Pa) | BP40: Dmax (mm)
A41: 44776.397 | B41: 8.349156e-08 | C41: 0.65388842 | D41: 60.390472 | E41: 0 | F41: =E41/60 -> 0 | G41: =F41*B41 -> 0 | H41: =17.285*G41^0.664 -> 0 | J41: 44781.397 | K41: 7.3400607e-07 | L41: 1.1429923 | M41: 60.974058 | N41: 0 | O41: =N41/60 -> 0 | P41: =O41*K41 -> 0 | Q41: =17.285*P41^0.664 -> 0 | S41: 45136.396 | T41: 0.0012371809 | U41: 0.99150227 | V41: 63.237731 | W41: 3550 | X41: =W41/60 -> 59.166667 | Y41: =T41*X41 -> 0.073199871 | Z41: =17.285*Y41^0.664 -> 3.04582 | AB41: 45151.396 | AC41: 0.00067921138 | AD41: 62.343558 | AE41: 566 | AF41: =AE41/60 -> 9.4333333 | AG41: =AF41*AC41 -> 0.0064072273 | AH41: =17.285*AG41^0.664 -> 0.60436367 | AJ41: 45166.396 | AK41: 0.0014438571 | AL41: 62.3158 | AM41: 2103 | AN41: =AM41/60 -> 35.05 | AO41: =AN41*AK41 -> 0.050607191 | AP41: =17.285*AO41^0.664 -> 2.3837807 | AR41: 45183.396 | AS41: 0.00045815336 | AT41: 0.29572638 | AU41: 63.179355 | AV41: 173 | AW41: =AV41/60 -> 2.8833333 | AX41: =AW41*AS41 -> 0.0013210089 | AY41: =17.285*AX41^0.664 -> 0.21181211 | BA41: 45031.115 | BB41: 0.0047222462 | BC41: 62.93365 | BD41: 106.11 | BE41: 40020 | BF41: =BE41/60 -> 667 | BG41: =BF41*BB41 -> 3.1497382 | BH41: =17.285*BG41^0.664 -> 37.027435 | BJ41: =BA1823 -> 45051.729 | BK41: =BC1823 -> 99.297599 | BL41: =BD1823 -> 119.84 | BM41: =BM36 -> 42.762443 | BN41: =BN36 -> 45044.125 | BO41: =BO36 -> 114.76 | BP41: =BP36 -> 101.10537
A42: 44776.407 | B42: 7.751085e-08 | C42: 0.66321231 | D42: 60.346197 | E42: 0 | F42: =E42/60 -> 0 | G42: =F42*B42 -> 0 | H42: =17.285*G42^0.664 -> 0 | J42: 44781.407 | K42: 8.2096639e-07 | L42: 1.1391713 | M42: 60.974058 | N42: 0 | O42: =N42/60 -> 0 | P42: =O42*K42 -> 0 | Q42: =17.285*P42^0.664 -> 0 | S42: 45136.406 | T42: 0.0014455957 | U42: 1.1451054 | V42: 63.237731 | W42: 5665 | X42: =W42/60 -> 94.416667 | Y42: =T42*X42 -> 0.13648832 | Z42: =17.285*Y42^0.664 -> 4.6065182 | AB42: 45151.406 | AC42: 0.00074816269 | AD42: 62.343558 | AE42: 591 | AF42: =AE42/60 -> 9.85 | AG42: =AF42*AC42 -> 0.0073694025 | AH42: =17.285*AG42^0.664 -> 0.66319985 | AJ42: 45166.406 | AK42: 0.0008861716 | AL42: 62.3158 | AM42: 1175 | AN42: =AM42/60 -> 19.583333 | AO42: =AN42*AK42 -> 0.017354194 | AP42: =17.285*AO42^0.664 -> 1.1712077 | AR42: 45183.406 | AS42: 0.0007042344 | AT42: 0.37677721 | AU42: 63.071137 | AV42: 427 | AW42: =AV42/60 -> 7.1166667 | AX42: =AW42*AS42 -> 0.0050118014 | AY42: =17.285*AX42^0.664 -> 0.51341116 | BA42: 45031.125 | BB42: 0.003904125 | BC42: 59.125991 | BD42: 106.11 | BE42: 40761 | BF42: =BE42/60 -> 679.35 | BG42: =BF42*BB42 -> 2.6522673 | BH42: =17.285*BG42^0.664 -> 33.033247 | BJ42: Dimensionless | BK42: =BK41/(1650*9.81*0.04364) -> 0.14057272 | BL42: =BL41/(1650*9.81*0.04364) -> 0.169654
A43: 44776.417 | B43: 1.4555067e-07 | C43: 0.7397278 | D43: 60.105067 | E43: 0 | F43: =E43/60 -> 0 | G43: =F43*B43 -> 0 | H43: =17.285*G43^0.664 -> 0 | J43: 44781.417 | K43: 7.562108e-07 | L43: 1.1265039 | M43: 60.951549 | N43: 0 | O43: =N43/60 -> 0 | P43: =O43*K43 -> 0 | Q43: =17.285*P43^0.664 -> 0 | S43: 45136.417 | T43: 0.0010477122 | U43: 0.89859415 | V43: 63.199403 | W43: 2228 | X43: =W43/60 -> 37.133333 | Y43: =T43*X43 -> 0.038905046 | Z43: =17.285*Y43^0.664 -> 2.0018583 | AB43: 45151.417 | AC43: 0.0010649934 | AD43: 62.343558 | AE43: 1032 | AF43: =AE43/60 -> 17.2 | AG43: =AF43*AC43 -> 0.018317886 | AH43: =17.285*AG43^0.664 -> 1.2139998 | AJ43: 45166.417 | AK43: 0.0013905419 | AL43: 62.3158 | AM43: 2086 | AN43: =AM43/60 -> 34.766667 | AO43: =AN43*AK43 -> 0.048344507 | AP43: =17.285*AO43^0.664 -> 2.3124688 | AR43: 45183.417 | AS43: 0.00074413637 | AT43: 0.37677721 | AU43: 63.071137 | AV43: 435 | AW43: =AV43/60 -> 7.25 | AX43: =AW43*AS43 -> 0.0053949887 | AY43: =17.285*AX43^0.664 -> 0.53915185 | BA43: 45031.135 | BB43: 0.0044288218 | BC43: 59.769842 | BD43: 105.98 | BE43: 40479 | BF43: =BE43/60 -> 674.65 | BG43: =BF43*BB43 -> 2.9879047 | BH43: =17.285*BG43^0.664 -> 35.753033
A44: 44776.428 | B44: 1.0303902e-07 | C44: 0.7233343 | D44: 59.519123 | E44: 0 | F44: =E44/60 -> 0 | G44: =F44*B44 -> 0 | H44: =17.285*G44^0.664 -> 0 | J44: 44781.428 | K44: 8.4164205e-07 | L44: 1.190277 | M44: 60.905992 | N44: 0 | O44: =N44/60 -> 0 | P44: =O44*K44 -> 0 | Q44: =17.285*P44^0.664 -> 0 | S44: 45136.427 | T44: 0.0015330688 | U44: 0.89859415 | V44: 63.074471 | W44: 2753 | X44: =W44/60 -> 45.883333 | Y44: =T44*X44 -> 0.070342307 | Z44: =17.285*Y44^0.664 -> 2.9663419 | AB44: 45151.427 | AC44: 0.0009117145 | AD44: 62.343558 | AE44: 628 | AF44: =AE44/60 -> 10.466667 | AG44: =AF44*AC44 -> 0.0095426118 | AH44: =17.285*AG44^0.664 -> 0.78735111 | AJ44: 45166.427 | AK44: 0.0013727592 | AL44: 62.3158 | AM44: 2325 | AN44: =AM44/60 -> 38.75 | AO44: =AN44*AK44 -> 0.05319442 | AP44: =17.285*AO44^0.664 -> 2.4640213 | AR44: 45183.427 | AS44: 0.0004591079 | AT44: 0.33439969 | AU44: 63.068643 | AV44: 299 | AW44: =AV44/60 -> 4.9833333 | AX44: =AW44*AS44 -> 0.0022878877 | AY44: =17.285*AX44^0.664 -> 0.30502401 | BA44: 45031.146 | BB44: 0.0043657583 | BC44: 59.769842 | BD44: 105.82 | BE44: 40606 | BF44: =BE44/60 -> 676.76667 | BG44: =BF44*BB44 -> 2.9545997 | BH44: =17.285*BG44^0.664 -> 35.487915
A45: 44776.438 | B45: 1.013813e-07 | C45: 0.71002782 | D45: 59.155652 | E45: 0 | F45: =E45/60 -> 0 | G45: =F45*B45 -> 0 | H45: =17.285*G45^0.664 -> 0 | J45: 44781.438 | K45: 1.143894e-06 | L45: 1.2284928 | M45: 60.951549 | N45: 0 | O45: =N45/60 -> 0 | P45: =O45*K45 -> 0 | Q45: =17.285*P45^0.664 -> 0 | S45: 45136.438 | T45: 0.0010573716 | U45: 0.85535298 | V45: 62.924494 | W45: 2104 | X45: =W45/60 -> 35.066667 | Y45: =T45*X45 -> 0.037078496 | Z45: =17.285*Y45^0.664 -> 1.9389494 | AB45: 45151.438 | AC45: 0.00071571484 | AD45: 62.212419 | AE45: 535 | AF45: =AE45/60 -> 8.9166667 | AG45: =AF45*AC45 -> 0.0063817907 | AH45: =17.285*AG45^0.664 -> 0.60276946 | AJ45: 45166.438 | AK45: 0.0013900389 | AL45: 62.3158 | AM45: 3145 | AN45: =AM45/60 -> 52.416667 | AO45: =AN45*AK45 -> 0.072861208 | AP45: =17.285*AO45^0.664 -> 3.0364559 | AR45: 45183.438 | AS45: 0.00059909397 | AT45: 0.39993655 | AU45: 63.068643 | AV45: 556 | AW45: =AV45/60 -> 9.2666667 | AX45: =AW45*AS45 -> 0.0055516041 | AY45: =17.285*AX45^0.664 -> 0.54949439 | BA45: 45031.156 | BB45: 0.0043233674 | BC45: 57.814718 | BD45: 105.75 | BE45: 39457 | BF45: =BE45/60 -> 657.61667 | BG45: =BF45*BB45 -> 2.8431185 | BH45: =17.285*BG45^0.664 -> 34.59308
A46: 44776.449 | B46: 1.1198406e-07 | C46: 0.72868923 | D46: 59.101038 | E46: 0 | F46: =E46/60 -> 0 | G46: =F46*B46 -> 0 | H46: =17.285*G46^0.664 -> 0 | J46: 44781.449 | K46: 9.9576696e-07 | L46: 1.2126181 | M46: 60.97547 | N46: 0 | O46: =N46/60 -> 0 | P46: =O46*K46 -> 0 | Q46: =17.285*P46^0.664 -> 0 | S46: 45136.448 | T46: 0.0006858932 | U46: 0.66228852 | V46: 62.750492 | W46: 639 | X46: =W46/60 -> 10.65 | Y46: =T46*X46 -> 0.0073047626 | Z46: =17.285*Y46^0.664 -> 0.65933152 | AB46: 45151.448 | AC46: 0.0010011793 | AD46: 62.212419 | AE46: 860 | AF46: =AE46/60 -> 14.333333 | AG46: =AF46*AC46 -> 0.014350236 | AH46: =17.285*AG46^0.664 -> 1.0323425 | AJ46: 45166.448 | AK46: 0.0017626679 | AL46: 62.3158 | AM46: 3379 | AN46: =AM46/60 -> 56.316667 | AO46: =AN46*AK46 -> 0.09926758 | AP46: =17.285*AO46^0.664 -> 3.728632 | AR46: 45183.448 | AS46: 0.0007392088 | AT46: 0.44894941 | AU46: 63.068643 | AV46: 592 | AW46: =AV46/60 -> 9.8666667 | AX46: =AW46*AS46 -> 0.0072935269 | AY46: =17.285*AX46^0.664 -> 0.65865796 | BA46: 45031.167 | BB46: 0.0045644899 | BC46: 62.93365 | BD46: 105.63 | BE46: 39872 | BF46: =BE46/60 -> 664.53333 | BG46: =BF46*BB46 -> 3.0332557 | BH46: =17.285*BG46^0.664 -> 36.112452
A47: 44776.459 | B47: 7.551592e-08 | C47: 0.66863319 | D47: 59.052608 | E47: 0 | F47: =E47/60 -> 0 | G47: =F47*B47 -> 0 | H47: =17.285*G47^0.664 -> 0 | J47: 44781.459 | K47: 9.5805424e-07 | L47: 1.2029581 | M47: 60.97547 | N47: 0 | O47: =N47/60 -> 0 | P47: =O47*K47 -> 0 | Q47: =17.285*P47^0.664 -> 0 | S47: 45136.458 | T47: 0.00039099546 | U47: 0.47569238 | V47: 62.542107 | W47: 76 | X47: =W47/60 -> 1.2666667 | Y47: =T47*X47 -> 0.00049526092 | Z47: =17.285*Y47^0.664 -> 0.11041783 | AB47: 45151.458 | AC47: 0.00075270095 | AD47: 62.150665 | AE47: 617 | AF47: =AE47/60 -> 10.283333 | AG47: =AF47*AC47 -> 0.0077402748 | AH47: =17.285*AG47^0.664 -> 0.68517833 | AJ47: 45166.458 | AK47: 0.0018154402 | AL47: 62.3158 | AM47: 3514 | AN47: =AM47/60 -> 58.566667 | AO47: =AN47*AK47 -> 0.10632428 | AP47: =17.285*AO47^0.664 -> 3.9025937 | AR47: 45183.458 | AS47: 0.00062267033 | AT47: 0.37677721 | AU47: 63.068643 | AV47: 401 | AW47: =AV47/60 -> 6.6833333 | AX47: =AW47*AS47 -> 0.0041615133 | AY47: =17.285*AX47^0.664 -> 0.4537872 | BA47: 45031.177 | BB47: 0.0042568091 | BC47: 58.466045 | BD47: 105.49 | BE47: 40024 | BF47: =BE47/60 -> 667.06667 | BG47: =BF47*BB47 -> 2.8395755 | BH47: =17.285*BG47^0.664 -> 34.56445
...

Sheet spring
A1: NEW | C1: Mobile | D1: Average | J1: full record
A2: Time | B2: Max Amp | C2: Tau (Pa) | D2: Tau (Pa) | E2: Ch1 Impulses | F2: Impulses/s | G2: Imp/s * MaxAmp | H2: Dmax (mm) | J2: time | K2: taum | AF2: interpol | AG2: excel | AN2: python
A3: 45003.569 | B3: 0.00033926958 | C3: 30.192112 | D3: 82.2 | E3: 41476 | F3: =E3/60 -> 691.26667 | G3: =F3*B3 -> 0.23452575 | H3: =17.285*G3^0.664 -> 6.5989661 | J3: 44986 | K3: 5.5094959 | AB3: Time | AC3: Dmax (mm) | AD3: Tau (Pa) | AH3: event | AI3: event_start | AJ3: event_peak | AK3: event_end | AL3: has_tauc_exceedance | AM3: first_exceedance_time | AN3: first_exceedance_tau | AO3: n_transport_events | AP3: n_exceedance_points | AQ3: total_exceedance_hours | AR3: max_Dmax_mm
A4: 45003.583 | B4: 0.00037135137 | C4: 29.540552 | D4: 82.2 | E4: 40799 | F4: =E4/60 -> 679.98333 | G4: =F4*B4 -> 0.25251274 | H4: =17.285*G4^0.664 -> 6.9308339 | J4: 44986.01 | K4: 7.3016945 | AB4: 45031.573 | AC4: 61.98688 | AH4: 1 | AI4: 45033.542 | AJ4: 45033.929 | AK4: 45034.458 | AL4: FALSE | AO4: 0 | AP4: 0 | AQ4: 0
A5: 45003.594 | B5: 0.00039006014 | C5: 31.45854 | D5: 82.33 | E5: 41688 | F5: =E5/60 -> 694.8 | G5: =F5*B5 -> 0.27101379 | H5: =17.285*G5^0.664 -> 7.2639972 | J5: 44986.021 | K5: 9.2207653 | AB5: 45035.656 | AC5: 46.26313 | AD5: 116.22 | AH5: 2 | AI5: 45034.458 | AJ5: 45034.846 | AK5: 45035.417 | AL5: FALSE | AO5: 0 | AP5: 0 | AQ5: 0
A6: 45003.604 | B6: 0.00042841734 | C6: 34.564747 | D6: 82.59 | E6: 41055 | F6: =E6/60 -> 684.25 | G6: =F6*B6 -> 0.29314456 | H6: =17.285*G6^0.664 -> 7.6526478 | J6: 44986.031 | K6: 9.2207653 | AB6: 45035.667 | AC6: 60.71043 | AD6: 116.89 | AF6: =AI24 -> 115.78883 | AG6: =AD5 -> 116.22 | AH6: 3 | AI6: 45035.417 | AJ6: 45035.752 | AK6: 45036.458 | AL6: TRUE | AM6: 45035.656 | AN6: 118.22733 | AO6: 1 | AP6: 8 | AQ6: 2 | AR6: 60.71043
A7: 45003.615 | B7: 0.00038153344 | C7: 32.718214 | D7: 82.75 | E7: 41552 | F7: =E7/60 -> 692.53333 | G7: =F7*B7 -> 0.26422463 | H7: =17.285*G7^0.664 -> 7.1426546 | J7: 44986.042 | K7: 7.3123037 | AB7: 45035.677 | AC7: 45.34135 | AD7: 117.71 | AF7: =AI30 -> 108.17 | AG7: =AD13 -> 108.17 | AH7: 4 | AI7: 45037.5 | AJ7: 45037.773 | AK7: 45038.396 | AL7: TRUE | AM7: 45037.948 | AN7: 108.51115 | AO7: 5 | AP7: 5 | AQ7: 1.25 | AR7: 45.71622
A8: 45003.625 | B8: 0.00047407306 | C8: 34.564747 | D8: 82.8 | E8: 40860 | F8: =E8/60 -> 681 | G8: =F8*B8 -> 0.32284375 | H8: =17.285*G8^0.664 -> 8.1590638 | J8: 44986.052 | K8: 9.2095991 | AB8: 45035.688 | AC8: 45.27951 | AD8: 118.09 | AF8: =AI38 -> 106.26264 | AG8: =AD21 -> 106.31 | AH8: 5 | AI8: 45038.583 | AJ8: 45038.971 | AK8: 45039.438 | AL8: TRUE | AM8: 45038.646 | AN8: 106.97061 | AO8: 6 | AP8: 7 | AQ8: 1.75 | AR8: 46.06356
A9: 45003.635 | B9: 0.00042007337 | C9: 32.718214 | D9: 82.92 | E9: 40744 | F9: =E9/60 -> 679.06667 | G9: =F9*B9 -> 0.28525783 | H9: =17.285*G9^0.664 -> 7.515314 | J9: 44986.062 | K9: 10.529934 | AB9: 45035.698 | AC9: 47.58757 | AD9: 118.09 | AF9: =AI45 -> 113.54652 | AG9: =AD29 -> 113.56 | AH9: 6 | AI9: 45039.479 | AJ9: 45039.846 | AK9: 45040.458 | AL9: TRUE | AM9: 45039.719 | AN9: 113.7204 | AO9: 7 | AP9: 7 | AQ9: 1.75 | AR9: 47.355
A10: 45003.646 | B10: 0.0004610992 | C10: 36.602484 | D10: 83.26 | E10: 40582 | F10: =E10/60 -> 676.36667 | G10: =F10*B10 -> 0.31187213 | H10: =17.285*G10^0.664 -> 7.9738823 | J10: 44986.073 | K10: 10.529934 | AB10: 45035.708 | AC10: 46.52886 | AD10: 118.09 | AH10: 7 | AI10: 45040.458 | AJ10: 45040.742 | AK10: 45041.458 | AL10: FALSE | AO10: 0 | AP10: 0 | AQ10: 0
A11: 45003.656 | B11: 0.00044448718 | C11: 36.602484 | D11: 83.49 | E11: 40899 | F11: =E11/60 -> 681.65 | G11: =F11*B11 -> 0.30298469 | H11: =17.285*G11^0.664 -> 7.8222684 | J11: 44986.083 | K11: 14.602154 | AB11: 45035.719 | AC11: 44.24524 | AD11: 118.09 | AF11: =AI52 -> 112.33125 | AG11: =AD36 -> 112.34 | AH11: 8 | AI11: 45043.5 | AJ11: 45043.867 | AK11: 45044.5 | AL11: TRUE | AM11: 45043.646 | AN11: 112.6632 | AO11: 8 | AP11: 9 | AQ11: 2.25 | AR11: 101.105
A12: 45003.667 | B12: 0.00050447863 | C12: 38.836464 | D12: 83.72 | E12: 41331 | F12: =E12/60 -> 688.85 | G12: =F12*B12 -> 0.3475101 | H12: =17.285*G12^0.664 -> 8.5678482 | J12: 44986.094 | K12: 11.206124 | AB12: 45035.729 | AC12: 44.17113 | AD12: 118.09 | AF12: =AI59 -> 115.16063 | AG12: =AD46 -> 115.14 | AH12: 9 | AI12: 45045.5 | AJ12: 45045.846 | AK12: 45046.5 | AL12: TRUE | AM12: 45046.344 | AN12: 114.89098 | AO12: 5 | AP12: 5 | AQ12: 1.25 | AR12: 44.466
A13: 45003.677 | B13: 0.0004621351 | C13: 38.096997 | D13: 84.01 | E13: 40141 | F13: =E13/60 -> 669.01667 | G13: =F13*B13 -> 0.30917609 | H13: =17.285*G13^0.664 -> 7.9280448 | J13: 44986.104 | K13: 12.549625 | AB13: 45037.948 | AC13: 45.47138 | AD13: 108.17 | AF13: =AI66 -> 115.21349 | AG13: =AD51 -> 115.91 | AH13: 10 | AI13: 45046.5 | AJ13: 45046.825 | AK13: 45047.458 | AL13: TRUE | AM13: 45046.562 | AN13: 116.55532 | AO13: 6 | AP13: 24 | AQ13: 6 | AR13: 47.503
A14: 45003.688 | B14: 0.00051127134 | C14: 36.602484 | D14: 84.09 | E14: 40006 | F14: =E14/60 -> 666.76667 | G14: =F14*B14 -> 0.34089869 | H14: =17.285*G14^0.664 -> 8.4592645 | J14: 44986.115 | K14: 10.529934 | AB14: 45038.281 | AC14: 44.75703 | AD14: 107.76 | AH14: 11 | AI14: 45047.458 | AJ14: 45047.981 | AK14: 45048.542 | AL14: FALSE | AO14: 0 | AP14: 0 | AQ14: 0
A15: 45003.698 | B15: 0.00043784814 | C15: 34.564747 | D15: 84.31 | E15: 41034 | F15: =E15/60 -> 683.9 | G15: =F15*B15 -> 0.29944434 | H15: =17.285*G15^0.664 -> 7.7614575 | J15: 44986.125 | K15: 12.549625 | AB15: 45038.333 | AC15: 44.80774 | AD15: 107.4 | AF15: =AI73 -> 115.37904 | AG15: =AD75 -> 115.36 | AH15: 12 | AI15: 45048.542 | AJ15: 45048.815 | AK15: 45049.479 | AL15: TRUE | AM15: 45048.635 | AN15: 118.40602 | AO15: 3 | AP15: 18 | AQ15: 4.5 | AR15: 54.056
A16: 45003.708 | B16: 0.00042293793 | C16: 34.564747 | D16: 84.78 | E16: 41052 | F16: =E16/60 -> 684.2 | G16: =F16*B16 -> 0.28937413 | H16: =17.285*G16^0.664 -> 7.5871493 | J16: 44986.135 | K16: 12.549625 | AB16: 45038.365 | AC16: 44.41661 | AD16: 107.3 | AF16: =AI80 -> 116.73995 | AG16: =AD88 -> 116.34 | AH16: 13 | AI16: 45049.479 | AJ16: 45049.804 | AK16: 45050.417 | AL16: TRUE | AM16: 45049.458 | AN16: 115.75512 | AO16: 20 | AP16: 54 | AQ16: 13.5 | AR16: 53.784
A17: 45003.719 | B17: 0.00046194704 | C17: 32.718214 | D17: 85.06 | E17: 41675 | F17: =E17/60 -> 694.58333 | G17: =F17*B17 -> 0.32086072 | H17: =17.285*G17^0.664 -> 8.1257522 | J17: 44986.146 | K17: 14.602154 | AB17: 45038.385 | AC17: 45.71622 | AD17: 107.22 | AF17: =AI87 -> 121.52933 | AG17: =AD134 -> 120.63 | AH17: 14 | AI17: 45050.458 | AJ17: 45050.783 | AK17: 45051.375 | AL17: TRUE | AM17: 45050.375 | AN17: 121.12197 | AO17: 11 | AP17: 29 | AQ17: 7.25 | AR17: 53.784
A18: 45003.729 | B18: 0.00047564928 | C18: 38.836464 | D18: 85.12 | E18: 41407 | F18: =E18/60 -> 690.11667 | G18: =F18*B18 -> 0.3282535 | H18: =17.285*G18^0.664 -> 8.2495906 | J18: 44986.156 | K18: 11.194617 | AB18: 45038.427 | AC18: 46.22954 | AD18: 106.5 | AH18: 15 | AI18: 45051.417 | AJ18: 45051.783 | AK18: 45052.375 | AL18: FALSE | AO18: 0 | AP18: 0 | AQ18: 0
A19: 45003.74 | B19: 0.00088248321 | C19: 40.323477 | D19: 85.26 | E19: 41464 | F19: =E19/60 -> 691.06667 | G19: =F19*B19 -> 0.60985473 | H19: =17.285*G19^0.664 -> 12.446857 | J19: 44986.167 | K19: 12.549625 | AB19: 45038.469 | AC19: 44.70071 | AD19: 106.2
A20: 45003.75 | B20: 0.00093484034 | C20: 38.836464 | D20: 85.44 | E20: 41415 | F20: =E20/60 -> 690.25 | G20: =F20*B20 -> 0.64527354 | H20: =17.285*G20^0.664 -> 12.922285 | J20: 44986.177 | K20: 15.987649 | AB20: 45038.521 | AC20: 44.78042 | AD20: 106.13 | AH20: Event 3 | AI20: Interpolated Rising D50 | AK20: Interpolated Rising D25
A21: 45003.76 | B21: 0.0010144412 | C21: 42.550901 | D21: 85.47 | E21: 41533 | F21: =E21/60 -> 692.21667 | G21: =F21*B21 -> 0.70221311 | H21: =17.285*G21^0.664 -> 13.668623 | J21: 44986.188 | K21: 11.875872 | AB21: 45038.542 | AC21: 45.42628 | AD21: 106.31 | AI21: Total | AJ21: Dmax (mm) | AL21: Total | AM21: Dmax (mm)
A22: 45003.771 | B22: 0.00067653363 | C22: 38.096997 | D22: 85.62 | E22: 41204 | F22: =E22/60 -> 686.73333 | G22: =F22*B22 -> 0.46459819 | H22: =17.285*G22^0.664 -> 10.38984 | J22: 44986.198 | K22: 11.875872 | AB22: 45038.646 | AC22: 44.19458 | AD22: 106.66 | AH22: =A380 -> 45035.646 | AI22: =D380 -> 115.78 | AJ22: =H380 -> 43.851588
A23: 45003.781 | B23: 0.00049611092 | C23: 40.323477 | D23: 85.72 | E23: 40817 | F23: =E23/60 -> 680.28333 | G23: =F23*B23 -> 0.33749599 | H23: =17.285*G23^0.664 -> 8.4031041 | J23: 44986.208 | K23: 13.918406 | AB23: 45038.656 | AC23: 44.46058 | AD23: 106.76 | AH23: =AB5 -> 45035.656 | AI23: =AD5 -> 116.22 | AJ23: =AC5 -> 46.26313
A24: 45003.792 | B24: 0.00043272363 | C24: 38.096997 | D24: 85.74 | E24: 41118 | F24: =E24/60 -> 685.3 | G24: =F24*B24 -> 0.2965455 | H24: =17.285*G24^0.664 -> 7.7114853 | J24: 44986.219 | K24: 13.918406 | AB24: 45038.688 | AC24: 45.40006 | AD24: 107.55 | AH24: =_xlfn.FORECAST.LINEAR(AJ24,AH22:AH23,AJ22:AJ23) -> 45035.646 | AI24: =_xlfn.FORECAST.LINEAR(AJ24,AI22:AI23,AJ22:AJ23) -> 115.78883 | AJ24: 43.9 | AK24: =_xlfn.FORECAST.LINEAR(AM24,AK22:AK23,AM22:AM23) -> #DIV/0! | AL24: =_xlfn.FORECAST.LINEAR(AM24,AL22:AL23,AM22:AM23) -> #DIV/0! | AM24: 24.3
A25: 45003.802 | B25: 0.00045373906 | C25: 42.550901 | D25: 85.75 | E25: 41494 | F25: =E25/60 -> 691.56667 | G25: =F25*B25 -> 0.31379081 | H25: =17.285*G25^0.664 -> 8.0064223 | J25: 44986.229 | K25: 13.90664 | N25: D50 | O25: 44986 | P25: 44 | AB25: 45038.74 | AC25: 46.06356 | AD25: 109.34 | AH25: Dimensionless | AI25: =AI24/(1650*9.81*0.04364) -> 0.16391888 | AK25: Dimensionless | AL25: =AL24/(1650*9.81*0.04364) -> #DIV/0!
A26: 45003.812 | B26: 0.000470571 | C26: 44.046561 | D26: 85.75 | E26: 41136 | F26: =E26/60 -> 685.6 | G26: =F26*B26 -> 0.32262348 | H26: =17.285*G26^0.664 -> 8.155367 | J26: 44986.24 | K26: 15.975782 | O26: 45059.844 | P26: 44 | AB26: 45039.083 | AC26: 44.54426 | AD26: 111.64
A27: 45003.823 | B27: 0.00048103402 | C27: 46.186479 | D27: 85.75 | E27: 41334 | F27: =E27/60 -> 688.9 | G27: =F27*B27 -> 0.33138434 | H27: =17.285*G27^0.664 -> 8.3017532 | J27: 44986.25 | K27: 18.054224 | N27: D84 | O27: 44986 | P27: 82 | AB27: 45039.115 | AC27: 45.63105 | AD27: 111.62 | AH27: Event 4 | AI27: Interpolated Rising D50 | AK27: Interpolated Rising D25
