Workbook

Sheet Sheet1
A1: Experiment Hysteresis | B1: Clockwise | C1: Counter-clockwise
A4: SSC (mg/L) | B4: Aich | C4: Peak Constituent (mg/L) | F4: Max Depth (cm) | G4: Armor Moved? | H4: Largest moved size | I4: % bed moved | J4: % moved >44 mm
A5: Experiment 2 | B5: 0.4534368 | C5: =MAX('constituent correlations'!F4:F17) -> 167.04417 | E5: Experiment 2 | F5: =MAX('constituent correlations'!D4:D17) -> 22.75 | G5: yes | H5: 128 | I5: 71.428571 | J5: 85.714286
A6: Experiment 3 | B6: 0.14144997 | C6: =MAX('constituent correlations'!F18:F33) -> 162.54186 | E6: Experiment 3 | F6: =MAX('constituent correlations'!D18:D33) -> 21.992 | G6: yes | H6: 128 | I6: 77.272727 | J6: 61.538462
A7: Experiment 4 | B7: 0.13607882 | C7: =MAX('constituent correlations'!F34:F46) -> 174.67614 | E7: Experiment 4 | F7: =MAX('constituent correlations'!D34:D46) -> 21.642 | G7: yes | H7: 90 | I7: 36.363636 | J7: 30.769231
A8: Experiment 5 | B8: 0.61769732 | C8: =MAX('constituent correlations'!F47:F58) -> 287.82895 | E8: Experiment 5 | F8: =MAX('constituent correlations'!D47:D58) -> 21.291 | G8: yes | H8: 128 | I8: 40 | J8: 40
A9: Experiment 6 | B9: 0.66455526 | C9: =MAX('constituent correlations'!F59:F71) -> 243.34663 | E9: Experiment 6 | F9: =MAX('constituent correlations'!D59:D71) -> 23.275 | G9: yes | H9: 64 | I9: 47.826087 | J9: 33.333333
A10: Experiment 7 | B10: 0.10896195 | C10: =MAX('constituent correlations'!F72:F82) -> 44.89063 | E10: Experiment 7 | F10: =MAX('constituent correlations'!D72:D82) -> 10.617 | G10: no | H10: - | I10: - | J10: -
A11: Experiment 8 | B11: 0.11013086 | C11: =MAX('constituent correlations'!F83:F92) -> 240.0198 | D11: =C10/C11 -> 0.18702887 | E11: Experiment 8 | F11: =MAX('constituent correlations'!D83:D92) -> 9.392 | G11: armor removed | H11: - | I11: - | J11: -
A13: POC (mg/L) | B13: Aich | C13: Peak Constituent (mg/L)
A14: Experiment 2 | B14: 0.26221156 | C14: =MAX('constituent correlations'!H4:H17) -> 12.330497
A15: Experiment 3 | B15: 0.15997395 | C15: =MAX('constituent correlations'!H18:H33) -> 12.041211
A16: Experiment 4 | B16: -0.0025566841 | C16: =MAX('constituent correlations'!H34:H46) -> 10.930144
A17: Experiment 5 | B17: 0.62020718 | C17: =MAX('constituent correlations'!H47:H58) -> 24.660151
A18: Experiment 6 | B18: 0.78199949 | C18: =MAX('constituent correlations'!H59:H71) -> 20.726108
A19: Experiment 7 | B19: -0.50127991 | C19: =MAX('constituent correlations'!H72:H82) -> 4.9322235
A20: Experiment 8 | B20: 0.091527186 | C20: =MAX('constituent correlations'!H83:H92) -> 17.196571 | D20: =C19/C20 -> 0.28681437
A22: DOC (mg/L) | B22: Aich | C22: Peak Constituent (mg/L)
A23: Experiment 2 | B23: 0.082872286 | C23: =MAX('constituent correlations'!G4:G17) -> 2.64
A24: Experiment 3 | B24: -0.12086439 | C24: =MAX('constituent correlations'!G18:G33) -> 3.009
A25: Experiment 4 | B25: 0.01197471 | C25: =MAX('constituent correlations'!G34:G46) -> 2.898
A26: Experiment 5 | B26: -0.093327819 | C26: =MAX('constituent correlations'!G47:G58) -> 2.303
A27: Experiment 6 | B27: -0.073285475 | C27: =MAX('constituent correlations'!G59:G71) -> 2.883
A28: Experiment 7 | B28: -0.0086314058 | C28: =MAX('constituent correlations'!G72:G82) -> 3.641
A29: Experiment 8 | B29: 0.11666546 | C29: =MAX('constituent correlations'!G83:G92) -> 3.135 | D29: =C28/C29 -> 1.1614035
A31: PP (mg/L) | B31: Aich | C31: Peak Constituent (mg/L)
A32: Experiment 2 | B32: 0.39025509 | C32: 0.022338386
A33: Experiment 3
A34: Experiment 4
A35: Experiment 5
A36: Experiment 6 | B36: 0.54200255 | C36: 0.023321472
A37: Experiment 7
A38: Experiment 8 | D38: =C37/C38 -> #DIV/0!
A40: SRP (mg/L) | B40: Aich | C40: Peak Constituent (mg/L)
A41: Experiment 2 | B41: -0.26955873 | C41: 0.0298764
A42: Experiment 3
A43: Experiment 4
A44: Experiment 5
A45: Experiment 6 | B45: 0.0026807257 | C45: 0.0263398
A46: Experiment 7
...

Sheet constituent correlations
A3: Experiment 2 | B3: Lab ID | C3: Date_Time | D3: Depth | E3: SSC (uL/L) | F3: SSC (mg/L) | G3: DOC (mg/L) | H3: POC (mg/L) | I3: PP (mg/L) | J3: TP (mg/L) | K3: SRP (mg/L)
A4: Experiment 2 | B4: 1 | C4: 44775.498 | D4: 9.275 | E4: 97.69 | F4: 167.04417 | G4: 2.64 | H4: 10.974524 | I4: 0.010039344 | J4: 0.0601808 | K4: 0.0245715
A5: Experiment 2 | B5: 2 | C5: 44775.498 | D5: 22.75 | E5: 347.61 | F5: 145.07862 | G5: 2.384 | H5: 12.330497 | I5: 0.022338386 | J5: 0.0365312 | K5: 0.0174983
A6: Experiment 2 | B6: 3 | C6: 44775.498 | D6: 19.25 | E6: 191.85 | F6: 76.137885 | G6: 2.284 | I6: 0.0098099758 | J6: 0.0328928 | K6: 0.0210349
A7: Experiment 2 | B7: 4 | C7: 44775.498 | D7: 16.1 | E7: 176.97 | F7: 47.967685 | G7: 2.423 | H7: 4.9671491 | I7: 0.010318701 | J7: 0.0328928 | K7: 0.0298764
A8: Experiment 2 | B8: 5 | C8: 44775.499 | D8: 13.884 | E8: 127.27 | F8: 67.326074 | G8: 2.488 | H8: 8.8903535 | I8: 0.0062101564 | J8: 0.034712 | K8: 0.0263398
A9: Experiment 2 | B9: 6 | C9: 44775.499 | D9: 12.775 | E9: 83.04 | F9: 61.268422 | G9: 2.473 | I9: 0.005242666 | J9: 0.089288 | K9: 0.0281081
A10: Experiment 2 | B10: 7 | C10: 44775.499 | D10: 12.134 | E10: 68.69 | F10: 40.782355 | G10: 2.314 | I10: 0.0032996878 | J10: 0.0383504 | K10: 0.0281081
A11: Experiment 2 | B11: 8 | C11: 44775.499 | D11: 11.959 | E11: 62.04 | F11: 43.350237 | G11: 2.402 | I11: 0.0026005392 | J11: 0.034712 | K11: 0.0298764
A12: Experiment 2 | B12: 9 | C12: 44775.499 | D12: 11.959 | E12: 61.07 | F12: 37.341299 | G12: 2.278 | I12: 0.0026185007 | J12: 0.0401696 | K12: 0.0245715
A13: Experiment 2 | B13: 10 | C13: 44775.499 | D13: 11.784 | E13: 48.37 | F13: 22.213081 | G13: 2.273 | I13: 0.0043689279 | J13: 0.0383504 | K13: 0.0281081
A14: Experiment 2 | B14: 11 | C14: 44775.499 | D14: 11.959 | E14: 29.69 | F14: 20.673117 | G14: 2.301 | I14: 0.0031173928 | J14: 0.0328928 | K14: 0.0263398
A15: Experiment 2 | B15: 12 | C15: 44775.499 | D15: 11.667 | E15: 28.69 | F15: 12.548101 | G15: 2.313 | H15: 3.2415982 | I15: 0.0025711584 | J15: 0.0365312 | K15: 0.0192666
A16: Experiment 2 | B16: 13 | C16: 44775.499 | D16: 11.492 | E16: 22.43 | F16: 10.726958 | G16: 2.308 | I16: 0.0026005392 | J16: 0.034712 | K16: 0.0210349
A17: Experiment 2 | B17: 14 | C17: 44775.5 | D17: 11.667 | E17: 0 | F17: 6.5843621 | G17: 2.214 | I17: 0.0022886277 | J17: 0.0383504 | K17: 0.0228032
A18: Experiment 3 | B18: 15 | C18: 44775.079 | D18: 10.092 | E18: 31.7 | F18: 22.819886 | G18: 2.718 | H18: 3.3278898
A19: Experiment 3 | B19: 16 | C19: 44775.079 | D19: 10.383 | E19: 93.36 | F19: 66.633761 | G19: 2.682 | H19: 6.6628506
A20: Experiment 3 | B20: 17 | C20: 44775.079 | D20: 21.992 | E20: 229.76 | F20: 162.54186 | G20: 2.644 | H20: 12.041211
A21: Experiment 3 | B21: 18 | C21: 44775.079 | D21: 18.317 | E21: 127.13 | F21: 89.561961 | G21: 2.752
A22: Experiment 3 | B22: 19 | C22: 44775.079 | D22: 15.983 | E22: 187.73 | F22: 87.538195 | G22: 2.808 | H22: 8.0581973
A23: Experiment 3 | B23: 20 | C23: 44775.08 | D23: 14.525 | E23: 112.47 | F23: 67.359667 | G23: 3.009
A24: Experiment 3 | B24: 21 | C24: 44775.08 | D24: 13.533 | E24: 84.69 | F24: 61.637081 | G24: 2.784
A25: Experiment 3 | B25: 22 | C25: 44775.08 | D25: 13.708 | E25: 97.42 | F25: 37.633969 | G25: 2.756 | H25: 5.0565466
A26: Experiment 3 | B26: 23 | C26: 44775.08 | D26: 12.775 | E26: 78.81 | F26: 49.685326 | G26: 2.804 | H26: 3.736428
A27: Experiment 3 | B27: 24 | C27: 44775.08 | D27: 12.133 | E27: 72.82 | F27: 30.500371 | G27: 2.804
A28: Experiment 3 | B28: 25 | C28: 44775.08 | D28: 12.133 | E28: 55.81 | F28: 27.99045 | G28: 2.864
A29: Experiment 3 | B29: 26 | C29: 44775.08 | D29: 11.958 | E29: 45.61 | F29: 16.572754 | G29: 2.76 | H29: 2.7714443
A30: Experiment 3 | B30: 27 | C30: 44775.08 | D30: 11.317 | E30: 47.12 | F30: 18.36854 | G30: 2.769
A31: Experiment 3 | B31: 28 | C31: 44775.08 | D31: 11.667 | E31: 34.58 | F31: 6.4583838 | G31: 2.741
A32: Experiment 3 | B32: 29 | C32: 44775.081 | D32: 11.667 | E32: 34.63 | F32: 11.361792 | G32: 2.752
A33: Experiment 3 | B33: 30 | C33: 44775.081 | D33: 11.492 | E33: 36.23 | F33: 11.501807 | G33: 2.739
A34: Experiment 4 | B34: 31 | C34: 44775.105 | D34: 8.342 | E34: 64.61 | F34: 52.169593 | G34: 2.898 | H34: 4.5952285
A35: Experiment 4 | B35: 32 | C35: 44775.105 | D35: 21.642 | E35: 275.96 | F35: 174.67614 | G35: 2.716 | H35: 10.930144
A36: Experiment 4 | B36: 33 | C36: 44775.105 | D36: 16.917 | E36: 159.29 | F36: 78.177539 | G36: 2.701
A37: Experiment 4 | B37: 34 | C37: 44775.105 | D37: 14.175 | E37: 121.26 | F37: 74.758733 | G37: 2.781 | H37: 8.9789966
A38: Experiment 4 | B38: 35 | C38: 44775.105 | D38: 12.95 | E38: 90.81 | F38: 52.974735 | G38: 2.831
A39: Experiment 4 | B39: 36 | C39: 44775.105 | D39: 12.6 | E39: 71.32 | F39: 40.183697 | G39: 2.763
A40: Experiment 4 | B40: 37 | C40: 44775.105 | D40: 11.667 | E40: 77.03 | F40: 43.398431 | G40: 2.814 | H40: 4.5994247
A41: Experiment 4 | B41: 38 | C41: 44775.106 | D41: 13.242 | E41: 143.56 | F41: 77.33443 | G41: 2.747
A42: Experiment 4 | B42: 39 | C42: 44775.106 | D42: 12.775 | E42: 97.7 | F42: 58.595362 | G42: 2.741
...
