Workbook

Sheet Spring
A1: Sample ID | B1: Volume filtered (mL) | C1: pre-filter weight (g) | D1: post-filter weight (g) | E1: Total sediment on filter - (inorganic + organic) (g) | F1: SS concentration (mg/L) | G1: LISST concentration (uL/L) | H1: mgC | I1: POC | J1: DOC | K1: Lab ID | L1: DateTime | M1: Respective Reach Turbidity | N1: Respective Site fDOM | O1: Downstream Turbidity | P1: Downstream fDOM | Q1: Upstream Turbidity | R1: Upstream fDOM | AG1: SSC (mg/L) | AH1: LISST (uL/L) | AI1: Respective Reach Turbidity | AJ1: Downstream Turbidity | AK1: Upstream Turbidity
A2: DOWN#1 4/15/23 | B2: 210 | C2: 0.2378 | D2: 0.2404 | E2: =D2-C2 -> 0.0026 | F2: =E2/B2*1000*1000 -> 12.380952 | J2: 3.729 | K2: 195 | L2: 45031.521 | M2: 6.3695391 | O2: 6.3695391 | Q2: 3.9399495 | T2: Downstream | AF2: DOWN#14 4/17/23 | AG2: 23.157895 | AH2: 106.21
A3: DOWN#2 4/15/23 | B3: 190 | C3: 0.2354 | D3: 0.2372 | E3: =D3-C3 -> 0.0018 | F3: =E3/B3*1000*1000 -> 9.4736842 | J3: 3.573 | K3: 196 | L3: 45031.688 | M3: 6.3686278 | O3: 6.3686278 | Q3: 3.9404717 | T3: Upstream | AF3: DOWN#15 4/17/23 | AG3: 15 | AH3: 51.233 | AK3: 17.909117
A4: DOWN#3 4/15/23 | B4: 200 | C4: 0.2345 | D4: 0.2355 | E4: =D4-C4 -> 0.001 | F4: =E4/B4*1000*1000 -> 5 | J4: 3.241 | K4: 197 | L4: 45031.854 | M4: 6.3677165 | O4: 6.3677165 | Q4: 3.940994 | AF4: DOWN#16 4/18/23 | AG4: 8.9473684 | AH4: 59.16 | AI4: 12.815806 | AJ4: 12.815806 | AK4: 12.502628
A5: DOWN#4 4/16/23 | B5: 200 | C5: 0.2352 | D5: 0.236 | E5: =D5-C5 -> 0.0008 | F5: =E5/B5*1000*1000 -> 4 | J5: 3.202 | K5: 198 | L5: 45032.021 | M5: 6.3668052 | O5: 6.3668052 | Q5: 3.9415163 | AF5: DOWN#17 4/18/23 | AG5: 9.5 | AH5: 48.47 | AI5: 12.045712 | AJ5: 12.045712 | AK5: 12.258318
A6: DOWN#7 4/16/23 | B6: 210 | C6: 0.2347 | D6: 0.2369 | E6: =D6-C6 -> 0.0022 | F6: =E6/B6*1000*1000 -> 10.47619 | J6: 3.234 | K6: 199 | L6: 45032.521 | M6: 6.3640714 | O6: 6.3640714 | Q6: 3.943083 | AF6: DOWN#1 4/18/23 | AG6: 23 | AH6: 78.71 | AI6: 21.162759 | AJ6: 21.162759 | AK6: 25.906272
A7: DOWN#8 4/16/23 | B7: 150 | C7: 0.2346 | D7: 0.236 | E7: =D7-C7 -> 0.0014 | F7: =E7/B7*1000*1000 -> 9.3333333 | J7: 3.293 | K7: 200 | L7: 45032.688 | M7: 6.3631601 | O7: 6.3631601 | Q7: 3.9436053 | AF7: DOWN#2 4/18/23 | AG7: 15 | AH7: 45.42 | AI7: 14.580477 | AJ7: 14.580477 | AK7: 15.555403
A8: DOWN#10 4/17/23 | B8: 145 | C8: 0.2371 | D8: 0.2385 | E8: =D8-C8 -> 0.0014 | F8: =E8/B8*1000*1000 -> 9.6551724 | J8: 3.179 | K8: 201 | L8: 45033.021 | M8: 6.3613375 | O8: 6.3613375 | Q8: 3.9446498 | AF8: DOWN#3 4/19/23 | AG8: 9.0909091 | AH8: 74.75 | AI8: 12.421141 | AJ8: 12.421141 | AK8: 12.1499
A9: DOWN#11 4/17/23 | B9: 150 | C9: 0.2333 | D9: 0.2339 | E9: =D9-C9 -> 0.0006 | F9: =E9/B9*1000*1000 -> 4 | J9: 3.111 | K9: 202 | L9: 45033.188 | M9: 6.3604262 | O9: 6.3604262 | Q9: 3.9451721 | AF9: DOWN#5 4/19/23 | AG9: 4.375 | AH9: 56.59 | AI9: 12.414953 | AJ9: 12.414953 | AK9: 10.979373
A10: DOWN#12 4/17/23 | B10: 200 | C10: 0.2363 | D10: 0.2366 | E10: =D10-C10 -> 0.0003 | F10: =E10/B10*1000*1000 -> 1.5 | J10: 3.026 | K10: 203 | L10: 45033.354 | M10: 6.3595149 | O10: 6.3595149 | Q10: 3.9456944 | AF10: DOWN#11 4/30/23 | AG10: 42 | AH10: 63.56 | AI10: 43.856736 | AJ10: 43.856736 | AK10: 38.639294
A11: DOWN#13 4/17/23 | B11: 200 | C11: 0.2355 | D11: 0.2366 | E11: =D11-C11 -> 0.0011 | F11: =E11/B11*1000*1000 -> 5.5 | J11: 3.091 | K11: 204 | L11: 45033.521 | M11: 5.2824903 | O11: 5.2824903 | Q11: 4.8290857 | AF11: DOWN#12 4/30/23 | AG11: 17.419355 | AH11: 85.89 | AI11: 16.958527 | AJ11: 16.958527 | AK11: 21.47596
A12: DOWN#14 4/17/23 | B12: 190 | C12: 0.2378 | D12: 0.2422 | E12: =D12-C12 -> 0.0044 | F12: =E12/B12*1000*1000 -> 23.157895 | G12: 106.21 | J12: 3.206 | K12: 205 | L12: 45033.688 | N12: 0.60768966 | P12: 0.60768966 | R12: 0.75582087 | AF12: DOWN#15 5/1/23 | AG12: 6 | AH12: 50.13 | AI12: 13.655056 | AJ12: 13.655056 | AK12: 16.170986
A13: DOWN#15 4/17/23 | B13: 200 | C13: 0.2352 | D13: 0.2382 | E13: =D13-C13 -> 0.003 | F13: =E13/B13*1000*1000 -> 15 | G13: 51.233 | J13: 3.663 | K13: 206 | L13: 45033.854 | N13: 0.67526826 | P13: 0.67526826 | Q13: 17.909117 | R13: 0.91088503 | AF13: DOWN#16 5/2/23 | AG13: 22.142857 | AH13: 44.99 | AI13: 22.052924 | AJ13: 22.052924
A14: DOWN#16 4/18/23 | B14: 190 | C14: 0.236 | D14: 0.2377 | E14: =D14-C14 -> 0.0017 | F14: =E14/B14*1000*1000 -> 8.9473684 | G14: 59.16 | H14: =0.009677027797625*27.38 -> 0.26495702 | I14: =H14/B14*1000 -> 1.3945106 | J14: 3.806 | K14: 222 | L14: 45034.021 | M14: 12.815806 | N14: 0.66271288 | O14: 12.815806 | P14: 0.66271288 | Q14: 12.502628 | R14: 0.88109358 | AF14: DOWN#17 5/2/23 | AG14: 10 | AH14: 35.73 | AI14: 12.440961 | AJ14: 12.440961 | AK14: 12.641193
A15: DOWN#17 4/18/23 | B15: 200 | C15: 0.2341 | D15: 0.236 | E15: =D15-C15 -> 0.0019 | F15: =E15/B15*1000*1000 -> 9.5 | G15: 48.47 | J15: 3.391 | K15: 207 | L15: 45034.188 | M15: 12.045712 | N15: 0.63474414 | O15: 12.045712 | P15: 0.63474414 | Q15: 12.258318 | R15: 0.81627632 | AF15: DOWN#18 5/2/23 | AG15: 6.4285714 | AH15: 31.62 | AI15: 9.0430762 | AJ15: 9.0430762 | AK15: 10.030398
A16: DOWN#18 4/18/23 | B16: 210 | C16: 0.2311 | D16: 0.232 | E16: =D16-C16 -> 0.0009 | F16: =E16/B16*1000*1000 -> 4.2857143 | G16: 0 | J16: 3.312 | K16: 223 | L16: 45034.354 | M16: 10.672197 | N16: 0.62033359 | O16: 10.672197 | P16: 0.62033359 | Q16: 12.736497 | R16: 0.76243801 | AF16: DOWN#19 5/2/23 | AG16: 18 | AH16: 25.42 | AI16: 11.007817 | AJ16: 11.007817
A17: DOWN#19 4/18/23 | G17: 0 | J17: 3.353 | K17: 224 | L17: 45034.521 | M17: 12.451086 | N17: 0.57870334 | O17: 12.451086 | P17: 0.57870334 | Q17: 11.800687 | R17: 0.67033505 | AF17: DOWN#1 5/3/23 | AG17: 20.666667 | AH17: 68.76 | AI17: 20.03069 | AJ17: 20.03069 | AK17: 22.228124
A18: DOWN#1 4/18/23 | B18: 200 | C18: 0.2307 | D18: 0.2353 | E18: =D18-C18 -> 0.0046 | F18: =E18/B18*1000*1000 -> 23 | G18: 78.71 | J18: 3.514 | K18: 225 | L18: 45034.688 | M18: 21.162759 | N18: 0.64280019 | O18: 21.162759 | P18: 0.64280019 | Q18: 25.906272 | R18: 0.81158338 | AF18: DOWN#3 5/4/23 | AG18: 11.875 | AH18: 50.92 | AI18: 10.664317 | AJ18: 10.664317 | AK18: 12.378682
A19: DOWN#2 4/18/23 | B19: 200 | C19: 0.229 | D19: 0.232 | E19: =D19-C19 -> 0.003 | F19: =E19/B19*1000*1000 -> 15 | G19: 45.42 | J19: 3.654 | K19: 226 | L19: 45034.896 | M19: 14.580477 | N19: 0.75155197 | O19: 14.580477 | P19: 0.75155197 | Q19: 15.555403 | R19: 0.95340234 | AF19: DOWN#9 5/4/23 | AG19: 9.3333333 | AH19: 33.08 | AI19: 9.9651312 | AJ19: 9.9651312 | AK19: 9.3933083
A20: DOWN#3 4/19/23 | B20: 220 | C20: 0.2285 | D20: 0.2305 | E20: =D20-C20 -> 0.002 | F20: =E20/B20*1000*1000 -> 9.0909091 | G20: 74.75 | J20: 3.576 | K20: 227 | L20: 45035.104 | M20: 12.421141 | N20: 0.68398085 | O20: 12.421141 | P20: 0.68398085 | Q20: 12.1499 | R20: 0.86879868 | AF20: DOWN#10 5/4/23 | AG20: 7.1428571 | AH20: 77.49 | AI20: 8.4859851 | AJ20: 8.4859851 | AK20: 7.5067933
A21: DOWN#4 4/19/23 | B21: 200 | C21: 0.2347 | D21: 0.2362 | E21: =D21-C21 -> 0.0015 | F21: =E21/B21*1000*1000 -> 7.5 | G21: 0 | J21: 3.389 | K21: 228 | L21: 45035.312 | M21: 10.916757 | N21: 0.63628066 | O21: 10.916757 | P21: 0.63628066 | Q21: 11.530608 | R21: 0.78447287 | AF21: UP#14 4/17/23 | AG21: 16 | AH21: 103.31
A22: DOWN#5 4/19/23 | B22: 160 | C22: 0.2354 | D22: 0.2361 | E22: =D22-C22 -> 0.0007 | F22: =E22/B22*1000*1000 -> 4.375 | G22: 56.59 | J22: 3.226 | K22: 229 | L22: 45035.521 | M22: 12.414953 | N22: 0.60410146 | O22: 12.414953 | P22: 0.60410146 | Q22: 10.979373 | R22: 0.67365488 | AF22: UP#15 4/17/23 | AG22: 0.5 | AH22: 65.48 | AI22: 17.909117 | AK22: 17.909117
A23: DOWN#9 4/20/23 | B23: 150 | C23: 0.235 | G23: 0 | J23: 3.552 | K23: 230 | L23: 45036.667 | M23: 10.387337 | N23: 0.59383254 | O23: 10.387337 | P23: 0.59383254 | Q23: 10.915366 | R23: 0.66390773 | AF23: UP#16 4/17/23 | AG23: 6.3157895 | AH23: 73.68 | AI23: 12.502628 | AJ23: 12.815806 | AK23: 12.502628
A24: DOWN#10 4/20/23 | B24: 160 | C24: 0.2373 | D24: 0.2382 | E24: =D24-C24 -> 0.0009 | F24: =E24/B24*1000*1000 -> 5.625 | G24: 0 | J24: 3.323 | K24: 231 | L24: 45036.771 | M24: 9.4103997 | N24: 0.61654414 | O24: 9.4103997 | P24: 0.61654414 | Q24: 11.403409 | R24: 0.69074627 | AF24: UP#1 4/18/23 | AG24: 21.5 | AH24: 93.48 | AI24: 25.906272 | AJ24: 21.162759 | AK24: 25.906272
A25: DOWN#11 4/20/23 | B25: 150 | C25: 0.236 | D25: 0.237 | E25: =D25-C25 -> 0.001 | F25: =E25/B25*1000*1000 -> 6.6666667 | G25: 0 | J25: 3.316 | K25: 232 | L25: 45036.979 | M25: 8.6639274 | N25: 0.59535333 | O25: 8.6639274 | P25: 0.59535333 | Q25: 10.587694 | R25: 0.66556154 | AF25: UP#2 4/18/23 | AG25: 11.052632 | AH25: 53.79 | AI25: 15.555403 | AJ25: 14.580477 | AK25: 15.555403
A26: DOWN#12 4/21/23 | C26: 0.2349 | D26: 0.2358 | E26: =D26-C26 -> 0.0009 | G26: 0 | J26: 3.207 | K26: 233 | L26: 45037.188 | M26: 8.1745655 | N26: 0.57885261 | O26: 8.1745655 | P26: 0.57885261 | Q26: 8.1144904 | R26: 0.64485797 | AF26: UP#3 4/19/23 | AG26: 18 | AH26: 47.58 | AI26: 12.1499 | AJ26: 12.421141 | AK26: 12.1499
A27: DOWN#13 4/21/23 | C27: 0.2378 | D27: 0.2388 | E27: =D27-C27 -> 0.001 | G27: 27.23 | J27: 3.153 | K27: 234 | L27: 45037.396 | M27: 8.8986113 | N27: 0.56270766 | O27: 8.8986113 | P27: 0.56270766 | Q27: 8.4315058 | R27: 0.62673251 | AF27: UP#4 4/19/23 | AG27: 6.5 | AH27: 30.72 | AI27: 11.530608 | AJ27: 10.916757 | AK27: 11.530608
A28: DOWN#14 4/21/23 | C28: 0.2365 | D28: 0.2372 | E28: =D28-C28 -> 0.0007 | G28: 0 | J28: 3.287 | K28: 235 | L28: 45037.604 | M28: 8.9511043 | N28: 0.5545622 | O28: 8.9511043 | P28: 0.5545622 | Q28: 10.69543 | R28: 0.61314625 | AF28: UP#7 4/19/23 | AG28: 6 | AH28: 22.36 | AI28: 11.706153 | AJ28: 11.105797 | AK28: 11.706153
A29: DOWN#1 4/23/23 | B29: 145 | C29: 0.2306 | D29: 0.2321 | E29: =D29-C29 -> 0.0015 | F29: =E29/B29*1000*1000 -> 10.344828 | G29: 0 | J29: 3.244 | K29: 254 | L29: 45039.667 | M29: 9.3171799 | N29: 0.60670676 | O29: 9.3171799 | P29: 0.60670676 | Q29: 11.769332 | R29: 0.67674274 | AF29: UP#8 4/20/23 | AG29: 8.8888889 | AH29: 30.83 | AI29: 10.369592 | AJ29: 9.7756286 | AK29: 10.369592
A30: DOWN#2 4/23/23 | B30: 150 | C30: 0.2271 | D30: 0.2279 | E30: =D30-C30 -> 0.0008 | F30: =E30/B30*1000*1000 -> 5.3333333 | G30: 0 | J30: 3.338 | K30: 255 | L30: 45039.875 | M30: 9.2401946 | N30: 0.643451 | O30: 9.2401946 | P30: 0.643451 | Q30: 7.3864228 | R30: 0.76992602 | AF30: UP#12 4/20/23 | AG30: 4.6666667 | AH30: 24.91 | AI30: 10.587694 | AJ30: 8.6639274 | AK30: 10.587694
A31: DOWN#3 4/24/23 | B31: 140 | C31: 0.2321 | D31: 0.233 | E31: =D31-C31 -> 0.0009 | F31: =E31/B31*1000*1000 -> 6.4285714 | G31: 0 | J31: 3.201 | K31: 256 | L31: 45040.083 | M31: 6.6271816 | N31: 0.61361535 | O31: 6.6271816 | P31: 0.61361535 | Q31: 8.1630528 | R31: 0.68208074 | AF31: UP#16 4/21/23 | AG31: 17.857143 | AH31: 67.13 | AI31: 11.028182 | AJ31: 10.239104 | AK31: 11.028182
A32: DOWN#4 4/24/23 | B32: 140 | C32: 0.2348 | D32: 0.2357 | E32: =D32-C32 -> 0.0009 | F32: =E32/B32*1000*1000 -> 6.4285714 | G32: 0 | J32: 3.056 | K32: 257 | L32: 45040.292 | M32: 6.8340318 | N32: 0.59474125 | O32: 6.8340318 | P32: 0.59474125 | R32: 0.65887905 | AF32: UP#18 4/22/23 | AG32: 6.6666667 | AH32: 51.68 | AI32: 7.7667875 | AJ32: 7.6684761 | AK32: 7.7667875
A33: DOWN#5 4/24/23 | B33: 155 | C33: 0.2253 | D33: 0.2275 | E33: =D33-C33 -> 0.0022 | F33: =E33/B33*1000*1000 -> 14.193548 | G33: 0 | J33: 3.091 | K33: 258 | L33: 45040.5 | M33: 8.1550506 | N33: 0.54444331 | O33: 8.1550506 | P33: 0.54444331 | Q33: 7.7209831 | R33: 0.62723158 | AF33: UP#20 4/22/23 | AG33: 5.3333333 | AH33: 57.56 | AI33: 9.6661809 | AJ33: 11.663247 | AK33: 9.6661809
A34: DOWN#6 4/24/23 | B34: 95 | C34: 0.2382 | D34: 0.2396 | E34: =D34-C34 -> 0.0014 | F34: =E34/B34*1000*1000 -> 14.736842 | G34: 0 | J34: 3.26 | K34: 259 | L34: 45040.708 | M34: 13.708842 | N34: 0.67745766 | O34: 13.708842 | P34: 0.67745766 | Q34: 12.27374 | R34: 0.81189412 | AF34: UP#21 4/23/23 | AG34: 8 | AH34: 63.54 | AI34: 9.1230037 | AJ34: 8.1688236 | AK34: 9.1230037
A35: DOWN#7 4/24/23 | B35: 95 | C35: 0.2322 | D35: 0.234 | E35: =D35-C35 -> 0.0018 | F35: =E35/B35*1000*1000 -> 18.947368 | G35: 0 | J35: 3.37 | K35: 260 | L35: 45040.917 | M35: 10.142847 | N35: 0.6987929 | O35: 10.142847 | P35: 0.6987929 | Q35: 9.938079 | R35: 0.72860548 | AF35: UP#3 4/24/23 | AG35: 8.6666667 | AH35: 66.59 | AI35: 8.1630528 | AJ35: 6.6271816 | AK35: 8.1630528
A36: DOWN#8 4/25/23 | B36: 115 | C36: 0.2298 | D36: 0.2328 | E36: =D36-C36 -> 0.003 | F36: =E36/B36*1000*1000 -> 26.086957 | G36: 0 | J36: 3.246 | K36: 261 | L36: 45041.125 | M36: 8.9488771 | N36: 0.63710624 | O36: 8.9488771 | P36: 0.63710624 | Q36: 8.2618505 | R36: 0.66229624 | AF36: UP#6 4/24/23 | AG36: 15 | AH36: 27.12 | AI36: 12.27374 | AJ36: 13.708842 | AK36: 12.27374
A37: DOWN#9 4/25/23 | B37: 110 | C37: 0.2345 | D37: 0.2353 | E37: =D37-C37 -> 0.0008 | F37: =E37/B37*1000*1000 -> 7.2727273 | G37: 0 | J37: 2.949 | K37: 262 | L37: 45041.333 | M37: 8.6484639 | N37: 0.616714 | O37: 8.6484639 | P37: 0.616714 | Q37: 9.017802 | R37: 1.5277317 | AF37: UP#7 4/24/23 | AG37: 7.1428571 | AH37: 14.59 | AI37: 9.938079 | AJ37: 10.142847 | AK37: 9.938079
A38: DOWN#10 4/25/23 | C38: 0.2331 | D38: 0.2342 | E38: =D38-C38 -> 0.0011 | G38: 0 | J38: 3.094 | K38: 263 | L38: 45041.542 | M38: 9.1187322 | N38: 0.59804602 | O38: 9.1187322 | P38: 0.59804602 | Q38: 9.038301 | R38: 0.64996641 | AF38: UP#1 4/28/23 | AG38: 6.6666667 | AH38: 56.02 | AI38: 8.0249351 | AJ38: 6.8345388 | AK38: 8.0249351
A39: DOWN#11 4/25/23 | B39: 150 | C39: 0.2323 | D39: 0.2331 | E39: =D39-C39 -> 0.0008 | F39: =E39/B39*1000*1000 -> 5.3333333 | G39: 0 | J39: 3.32 | K39: 264 | L39: 45041.75 | M39: 8.1289062 | N39: 0.61784086 | O39: 8.1289062 | P39: 0.61784086 | Q39: 9.2480751 | R39: 1.0381982 | AF39: UP#10 4/30/23 | AG39: 12.666667 | AH39: 43.66 | AI39: 8.7500033 | AJ39: 8.3597603 | AK39: 8.7500033
A40: DOWN#12 4/25/23 | B40: 140 | C40: 0.2357 | D40: 0.2364 | E40: =D40-C40 -> 0.0007 | F40: =E40/B40*1000*1000 -> 5 | G40: 0 | J40: 2.996 | K40: 265 | L40: 45041.958 | M40: 7.2309412 | N40: 0.60023069 | O40: 7.2309412 | P40: 0.60023069 | Q40: 7.3846326 | R40: 1.1297351 | AF40: UP#11 4/30/23 | AG40: 45 | AH40: 85.5 | AI40: 38.639294 | AJ40: 43.856736 | AK40: 38.639294
...

Sheet Summer 
A1: Sample ID | B1: Volume filtered (mL) | C1: pre-filter weight (g) | D1: post-filter weight (g) | E1: Total sediment on filter - (inorganic + organic) (g) | F1: SS concentration (mg/L) | G1: LISST concentration (uL/L) | H1: mgC | I1: POC | J1: DOC | K1: PP (mg/L) | L1: SRP | M1: TP | N1: Lab ID | O1: DateTime | P1: Respective Reach Turbidity | Q1: Respective Site fDOM | R1: Downstream Turbidity | S1: Downstream fDOM | T1: Upstream Turbidity | U1: Upstream fDOM
A2: ST1-D1 | B2: 240.43 | C2: 0.2431 | D2: 0.3783 | E2: =D2-C2 -> 0.1352 | F2: =E2/B2*1000*1000 -> 562.32583 | G2: 339.78248 | H2: 12.420595 | I2: =H2/B2*1000 -> 51.659922 | J2: 9.179 | K2: 1.19 | L2: 0.062 | M2: 0.36 | N2: VC-BER-20 | O2: 44400.66 | P2: 92.5304 | Q2: 25.1484 | R2: 92.5304 | S2: 25.1484 | T2: 95.886 | U2: 18.796 | V2: Storm 1 (2021)
A3: ST1-D2 | B3: 257.18 | C3: 0.2412 | D3: 0.377 | E3: =D3-C3 -> 0.1358 | F3: =E3/B3*1000*1000 -> 528.03484 | G3: 457.12 | H3: 12.917668 | I3: =H3/B3*1000 -> 50.228119 | J3: 12.625 | K3: 1.63 | L3: 0.088 | M3: 0.445 | N3: VC-BER-21 | O3: 44400.673 | P3: 197.94776 | Q3: 25.114 | R3: 197.94776 | S3: 25.114 | T3: 137.9732 | U3: 17.6696 | V3: Storm 2 (2022)
A4: ST1-D5 | B4: 279.39 | C4: 0.2385 | D4: 0.2785 | E4: =D4-C4 -> 0.04 | F4: =E4/B4*1000*1000 -> 143.16905 | G4: 152.79 | H4: 4.05182 | I4: =H4/B4*1000 -> 14.50238 | J4: 13.388 | K4: 0.77 | L4: 0.088 | M4: 0.248 | N4: VC-BER-31 | O4: 44400.694 | P4: 78.19298 | Q4: 37.8446 | R4: 78.19298 | S4: 37.8446 | T4: 60.358 | U4: 27.986 | V4: Storm 3 (2022)
A5: ST1-D6 | B5: 297.24 | C5: 0.2438 | D5: 0.2684 | E5: =D5-C5 -> 0.0246 | F5: =E5/B5*1000*1000 -> 82.761405 | G5: 168.45 | H5: 3.4720829 | I5: =H5/B5*1000 -> 11.681075 | J5: 12.997 | K5: 0.5 | L5: 0.083 | M5: 0.214 | N5: VC-BER-22 | O5: 44400.705 | P5: 74.057744 | Q5: 40.2548 | R5: 74.057744 | S5: 40.2548 | T5: 45.712 | U5: 30.934 | V5: Storm 4 (2023)
A6: ST1-D10 | B6: 262.73 | C6: 0.2414 | D6: 0.2511 | E6: =D6-C6 -> 0.0097 | F6: =E6/B6*1000*1000 -> 36.920032 | G6: 43.15 | H6: 1.6843076 | I6: =H6/B6*1000 -> 6.4107929 | J6: 12.868 | K6: 0.1 | L6: 0.053 | M6: 0.097 | N6: VC-BER-23 | O6: 44400.805 | P6: 20.5702 | Q6: 52.5872 | R6: 20.5702 | S6: 52.5872 | T6: 13.3468 | U6: 39.0732 | V6: Storm 5 (2023)
A7: ST1-S18 | B7: 272.58 | C7: 0.2398 | D7: 0.2458 | E7: =D7-C7 -> 0.006 | F7: =E7/B7*1000*1000 -> 22.011886 | G7: 17.7 | H7: 1.3097206 | I7: =H7/B7*1000 -> 4.8049034 | J7: 11.551 | K7: 0.07 | L7: 0.047 | M7: 0.077 | N7: VC-BER-24 | O7: 44400.876 | P7: 9.0308 | Q7: 38.27 | R7: 16.9712 | S7: 54.2484 | T7: 9.0308 | U7: 38.27 | V7: Storm 6 (2023)
A8: ST1-U1 | B8: 223.25 | C8: 0.2401 | D8: 0.2555 | E8: =D8-C8 -> 0.0154 | F8: =E8/B8*1000*1000 -> 68.980963 | G8: 92.06 | H8: 2.479204 | I8: =H8/B8*1000 -> 11.105057 | J8: 4.522 | K8: 0.15 | L8: 0.042 | M8: 0.094 | N8: VC-BER-25 | O8: 44400.621 | P8: 10.092 | Q8: 16.56 | R8: 12.2292 | S8: 21.9376 | T8: 10.092 | U8: 16.56 | V8: Storm 7 (2023)
A9: ST1-U3 | B9: 207.27 | C9: 0.2415 | D9: 0.2673 | E9: =D9-C9 -> 0.0258 | F9: =E9/B9*1000*1000 -> 124.47532 | G9: 95.69 | H9: 6.1584313 | I9: =H9/B9*1000 -> 29.712121 | J9: 4.436 | K9: 0.28 | L9: 0.045 | M9: 0.12 | N9: VC-BER-26 | O9: 44400.626 | P9: 13.9256 | Q9: 16.9048 | R9: 18.771 | S9: 21.957 | T9: 13.9256 | U9: 16.9048
A10: ST1-U8 | B10: 254.44 | C10: 0.2419 | D10: 0.3333 | E10: =D10-C10 -> 0.0914 | F10: =E10/B10*1000*1000 -> 359.22025 | G10: 403.515 | H10: 10.503118 | I10: =H10/B10*1000 -> 41.279351 | J10: 12.442 | K10: 1.66 | L10: 0.09 | M10: 0.362 | N10: VC-BER-28 | O10: 44400.676 | P10: 126.0844 | Q10: 19.1732 | R10: 182.64056 | S10: 27.346 | T10: 126.0844 | U10: 19.1732
A11: ST1-U11 | B11: 315.87 | C11: 0.2401 | D11: 0.2673 | E11: =D11-C11 -> 0.0272 | F11: =E11/B11*1000*1000 -> 86.111375 | G11: 124.04 | H11: 3.0083666 | I11: =H11/B11*1000 -> 9.5240655 | J11: 12.977 | K11: 0.38 | L11: 0.083 | M11: 0.208 | N11: VC-BER-29 | O11: 44400.707 | P11: 43.2064 | Q11: 31.4764 | R11: 73.380716 | S11: 40.6742 | T11: 43.2064 | U11: 31.4764
A12: ST1-U15 | B12: 222.95 | C12: 0.2437 | D12: 0.252 | E12: =D12-C12 -> 0.0083 | F12: =E12/B12*1000*1000 -> 37.228078 | G12: 65.3 | H12: 1.4577907 | I12: =H12/B12*1000 -> 6.538644 | J12: 13.108 | K12: 0.13 | L12: 0.067 | M12: 0.132 | N12: VC-BER-27 | O12: 44400.749 | P12: 20.8056 | Q12: 37.244 | R12: 35.428628 | S12: 47.754 | T12: 20.8056 | U12: 37.244
A13: ST1-U24 | B13: 213.57 | C13: 0.2425 | D13: 0.249 | E13: =D13-C13 -> 0.0065 | F13: =E13/B13*1000*1000 -> 30.434986 | G13: 42.87 | H13: 1.2189465 | I13: =H13/B13*1000 -> 5.7074801 | J13: 12.073 | K13: 0.06 | L13: 0.048 | M13: 0.086 | N13: VC-BER-30 | O13: 44400.842 | P13: 10.3608 | Q13: 38.9992 | R13: 12.142 | S13: 54.304 | T13: 10.3608 | U13: 38.9992
A14: ST2-U1 | B14: 119.53 | C14: 0.2401 | D14: 0.247 | E14: =D14-C14 -> 0.0069 | F14: =E14/B14*1000*1000 -> 57.726094 | G14: 206.82 | H14: 0.81093356 | I14: =H14/B14*1000 -> 6.7843517 | J14: 4.913 | K14: 0.48 | L14: 0.0149059 | M14: 0.099315 | N14: 95 | O14: 44776.626 | P14: 3.1412204 | Q14: 5.5433241 | R14: 16.7956 | S14: 17.3128 | T14: 3.1412204 | U14: 5.5433241
A15: ST2-U2 | B15: 118.59 | C15: 0.2432 | D15: 0.2489 | E15: =D15-C15 -> 0.0057 | F15: =E15/B15*1000*1000 -> 48.064761 | G15: 142.53 | H15: 0.67779828 | I15: =H15/B15*1000 -> 5.7154759 | J15: 6.55 | K15: 0.4 | L15: 0.0715306 | M15: 0.1012671 | N15: 96 | O15: 44776.637 | P15: 3.141253 | Q15: 5.5432513 | R15: 19.7892 | S15: 24.932 | T15: 3.141253 | U15: 5.5432513
A16: ST2-U3 | B16: 121.81 | C16: 0.2413 | D16: 0.248 | E16: =D16-C16 -> 0.0067 | F16: =E16/B16*1000*1000 -> 55.003694 | G16: 55.06 | H16: 0.63223098 | I16: =H16/B16*1000 -> 5.1903044 | J16: 8.035 | K16: 0.14 | L16: 0.0543716 | M16: 0.0856503 | N16: 97 | O16: 44776.658 | P16: 3.1413183 | Q16: 5.5431057 | R16: 10.3628 | S16: 33.9084 | T16: 3.1413183 | U16: 5.5431057
A17: ST2-U4 | B17: 117.35 | C17: 0.2371 | D17: 0.2424 | E17: =D17-C17 -> 0.0053 | F17: =E17/B17*1000*1000 -> 45.164039 | G17: 66.04 | H17: 0.64059154 | I17: =H17/B17*1000 -> 5.4588116 | J17: 8.691 | N17: 98 | O17: 44776.678 | P17: 3.1413836 | Q17: 5.54296 | R17: 13.1524 | S17: 36.4032 | T17: 3.1413836 | U17: 5.54296
A18: ST2-U5 | B18: 120.51 | C18: 0.2348 | D18: 0.2369 | E18: =D18-C18 -> 0.0021 | F18: =E18/B18*1000*1000 -> 17.42594 | G18: 39.15 | H18: 0.37952842 | I18: =H19/B19*1000 -> 2.088218 | J18: 8.124 | N18: 99 | O18: 44776.751 | P18: 3.1416121 | Q18: 5.5424502 | R18: 9.5941333 | S18: 37.711067 | T18: 3.1416121 | U18: 5.5424502
A19: ST2-U6 | B19: 122.31 | C19: 0.2332 | D19: 0.2346 | E19: =D19-C19 -> 0.0014 | F19: =E19/B19*1000*1000 -> 11.446325 | G19: 23.32 | H19: 0.25540995 | I19: =H18/B18*1000 -> 3.1493521 | J19: 8.073 | K19: 0.08 | L19: 0.0286331 | M19: 0.0446562 | N19: 100 | O19: 44776.762 | P19: 3.1416447 | Q19: 5.5423773 | R19: 9.1205333 | S19: 37.138933 | T19: 3.1416447 | U19: 5.5423773
A20: ST2-U7 | B20: 122.5 | C20: 0.2417 | D20: 0.2425 | E20: =D20-C20 -> 0.0008 | F20: =E20/B20*1000*1000 -> 6.5306122 | G20: 0 | H20: 0.26461862 | I20: =H20/B20*1000 -> 2.160152 | J20: 3.128 | N20: 101 | O20: 44776.793 | P20: 3.1417426 | Q20: 5.5421589 | R20: 7.762 | S20: 35.128933 | T20: 3.1417426 | U20: 5.5421589
A21: ST3-U1 | B21: 117.93 | C21: 0.2403 | D21: 0.2413 | E21: =D21-C21 -> 0.001 | F21: =E21/B21*1000*1000 -> 8.4796065 | G21: 0 | H21: 0.17978327 | I21: =H21/B21*1000 -> 1.5244914 | J21: 3.359 | N21: 102 | O21: 44781.572 | P21: 3.1567163 | Q21: 5.5087491 | R21: 5.6118667 | S21: 18.7592 | T21: 3.1567163 | U21: 5.5087491
A22: ST3-U2 | B22: 121 | C22: 0.242 | D22: 0.2433 | E22: =D22-C22 -> 0.0013 | F22: =E22/B22*1000*1000 -> 10.743802 | G22: 0 | H22: 0.20670824 | I22: =H22/B22*1000 -> 1.7083326 | J22: 3.424 | K22: 0.1 | L22: 0.0114741 | M22: 0.0290394 | N22: 103 | O22: 44781.582 | P22: 3.1567489 | Q22: 5.5086762 | R22: 7.4348 | S22: 20.030533 | T22: 3.1567489 | U22: 5.5086762
A23: ST3-U3 | B23: 120.98 | C23: 0.2378 | D23: 0.2402 | E23: =D23-C23 -> 0.0024 | F23: =E23/B23*1000*1000 -> 19.83799 | G23: 52.87 | H23: 0.37004992 | I23: =H23/B23*1000 -> 3.0587694 | J23: 3.9 | N23: 104 | O23: 44781.592 | P23: 3.1567816 | Q23: 5.5086034 | R23: 9.4148 | S23: 21.281867 | T23: 3.1567816 | U23: 5.5086034
A24: ST3-U4 | B24: 122.22 | C24: 0.2427 | D24: 0.2487 | E24: =D24-C24 -> 0.006 | F24: =E24/B24*1000*1000 -> 49.091802 | G24: 204.03 | H24: 0.6557215 | I24: =H24/B24*1000 -> 5.3650917 | J24: 5.279 | K24: 0.11 | L24: 0.0269172 | M24: 0.0638192 | N24: 105 | O24: 44781.603 | P24: 3.1568142 | Q24: 5.5085306 | R24: 15.5524 | S24: 26.152 | T24: 3.1568142 | U24: 5.5085306
A25: ST3-U5 | B25: 121.52 | C25: 0.239 | D25: 0.2433 | E25: =D25-C25 -> 0.0043 | F25: =E25/B25*1000*1000 -> 35.385122 | G25: 105.77 | H25: 0.62239774 | I25: =H25/B25*1000 -> 5.121772 | J25: 7.207 | N25: 106 | O25: 44781.613 | P25: 3.1568469 | Q25: 5.5084577 | R25: 20.7572 | S25: 31.2344 | T25: 3.1568469 | U25: 5.5084577
A26: ST3-U6 | B26: 122.46 | C26: 0.2376 | D26: 0.2405 | E26: =D26-C26 -> 0.0029 | F26: =E26/B26*1000*1000 -> 23.681202 | G26: 68.83 | H26: 0.27757089 | I26: =H26/B26*1000 -> 2.2666249 | J26: 7.75 | K26: 0.17 | L26: 0.0509398 | M26: 0.0739377 | N26: 107 | O26: 44781.641 | P26: 3.1569339 | Q26: 5.5082635 | R26: 14.5328 | S26: 35.32 | T26: 3.1569339 | U26: 5.5082635
A27: ST3-U7 | B27: 121.35 | C27: 0.2416 | D27: 0.2428 | E27: =D27-C27 -> 0.0012 | F27: =E27/B27*1000*1000 -> 9.8887515 | G27: 36.65 | H27: 0.23932675 | I27: =H27/B27*1000 -> 1.9722023 | J27: 8.41 | K27: 0.29 | L27: 0.0389285 | M27: 0.040752 | N27: 108 | O27: 44781.676 | P27: 3.1570427 | Q27: 5.5080207 | R27: 9.288 | S27: 37.6628 | T27: 3.1570427 | U27: 5.5080207
A28: ST3-U8 | B28: 119.95 | C28: 0.2441 | D28: 0.2450536 | E28: =D28-C28 -> 0.0009536025 | F28: =E28/B28*1000*1000 -> 7.95 | G28: 25.92 | H28: 0.18463064 | I28: =H28/B28*1000 -> 1.53923 | J28: 2.705 | N28: 110 | O28: 44781.697 | P28: 3.157108 | Q28: 5.5078751 | R28: 8.1485333 | S28: 38.017733 | T28: 3.157108 | U28: 5.5078751
A29: ST3-U9 | B29: 122.53 | C29: 0.2424 | D29: 0.2429 | E29: =D29-C29 -> 0.0005 | F29: =E29/B29*1000*1000 -> 4.0806333 | G29: 21.67 | H29: 0.1860829 | I29: =H29/B29*1000 -> 1.5186722 | J29: 8.421 | N29: 111 | O29: 44781.707 | P29: 3.1571406 | Q29: 5.5078023 | R29: 7.5998667 | S29: 38.203333 | T29: 3.1571406 | U29: 5.5078023
A30: ST3-U10 | B30: 121.54 | C30: 0.2365 | D30: 0.2367 | E30: =D30-C30 -> 0.0002 | F30: =E30/B30*1000*1000 -> 1.6455488 | G30: 19.05 | H30: 0.19585626 | I30: =H30/B30*1000 -> 1.6114551 | J30: 8.183 | N30: 112 | O30: 44781.728 | P30: 3.1572059 | Q30: 5.5076566 | R30: 6.7853333 | S30: 38.651333 | T30: 3.1572059 | U30: 5.5076566
A31: ST3-U11 | B31: 118.38 | C31: 0.2362 | D31: 0.2363 | E31: =D31-C31 -> 0.0001 | F31: =E31/B31*1000*1000 -> 0.84473729 | G31: 18.36 | H31: 0.20604216 | I31: =H31/B31*1000 -> 1.7405149 | J31: 2.742 | N31: 113 | O31: 44781.749 | P31: 3.1572712 | Q31: 5.5075109 | R31: 6.1841333 | S31: 39.0668 | T31: 3.1572712 | U31: 5.5075109
A32: ST3-U12 | B32: 122.39 | C32: 0.2398 | D32: 0.2405 | E32: =D32-C32 -> 0.0007 | F32: =E32/B32*1000*1000 -> 5.7194215 | G32: 0 | H32: 0.18269018 | I32: =H32/B32*1000 -> 1.4926888 | J32: 8.085 | K32: 0.06 | L32: 0.030349 | M32: 0.0348957 | N32: 114 | O32: 44781.759 | P32: 3.1573038 | Q32: 5.5074381 | R32: 5.9732 | S32: 39.0004 | T32: 3.1573038 | U32: 5.5074381
A33: ST4-D1 | B33: 100 | C33: 0.2336 | D33: 0.2523 | E33: =D33-C33 -> 0.0187 | F33: =E33/B33*1000*1000 -> 187 | H33: 2.9943163 | I33: =H33/B33*1000 -> 29.943163 | J33: 2.763 | K33: 0.0189 | N33: 439 | O33: 45136.619 | P33: 28.3628 | Q33: 6.9968 | R33: 28.3628 | S33: 6.9968 | T33: 33.4372 | U33: 6.95
A34: ST4-D2 | B34: 90 | C34: 0.2349 | D34: 0.2448 | E34: =D34-C34 -> 0.0099 | F34: =E34/B34*1000*1000 -> 110 | G34: 271.06 | H34: 0.86155237 | I34: =H34/B34*1000 -> 9.5728041 | J34: 3.128 | K34: 0.0695 | N34: 440 | O34: 45136.63 | P34: 35.5732 | Q34: 7.1008 | R34: 35.5732 | S34: 7.1008 | T34: 39.592 | U34: 7.1948
A35: ST4-D3 | B35: 90 | C35: 0.2333 | D35: 0.2381 | E35: =D35-C35 -> 0.0048 | F35: =E35/B35*1000*1000 -> 53.333333 | G35: 249.509 | H35: 0.62402435 | I35: =H35/B35*1000 -> 6.9336039 | J35: 3.553 | K35: 0.0411 | N35: 441 | O35: 45136.64 | P35: 34.972 | Q35: 7.936 | R35: 34.972 | S35: 7.936 | T35: 37.0576 | U35: 8.0852
A36: ST4-D4 | B36: 100 | C36: 0.237 | D36: 0.245 | E36: =D36-C36 -> 0.008 | F36: =E36/B36*1000*1000 -> 80 | G36: 244.856 | H36: 0.74831808 | I36: =H36/B36*1000 -> 7.4831808 | J36: 3.926 | K36: 0.0757 | N36: 442 | O36: 45136.651 | P36: 32.5424 | Q36: 8.77 | R36: 32.5424 | S36: 8.77 | T36: 33.8844 | U36: 8.9596
A37: ST4-D5 | B37: 90 | C37: 0.2404 | D37: 0.2443 | E37: =D37-C37 -> 0.0039 | F37: =E37/B37*1000*1000 -> 43.333333 | G37: 233.25 | H37: 0.53337838 | I37: =H37/B37*1000 -> 5.9264265 | J37: 4.158 | K37: 0.0663 | N37: 443 | O37: 45136.661 | P37: 26.4848 | Q37: 9.6544 | R37: 26.4848 | S37: 9.6544 | T37: 26.9192 | U37: 9.9072
A38: ST4-D6 | B38: 90 | C38: 0.2381 | D38: 0.2464 | E38: 0.0083 | F38: =E38/B38*1000*1000 -> 92.222222 | G38: 124.5634 | H38: 0.74561144 | I38: =H38/B38*1000 -> 8.2845715 | J38: 4.571 | K38: 0.0365 | N38: 444 | O38: 45136.672 | P38: 20.574 | Q38: 10.4076 | R38: 20.574 | S38: 10.4076 | T38: 20.8976 | U38: 10.7044
A39: ST4-D7 | B39: 90 | C39: 0.2413 | D39: 0.246 | E39: 0.0047 | F39: =E39/B39*1000*1000 -> 52.222222 | G39: 9.89 | H39: 0.93145151 | I39: =H39/B39*1000 -> 10.349461 | J39: 5.15 | K39: 0.0212 | N39: 445 | O39: 45136.682 | P39: 17.004 | Q39: 10.906 | R39: 17.004 | S39: 10.906 | T39: 17.0116 | U39: 11.2376
A40: ST4-U1 | B40: 90 | C40: 0.2368 | D40: 0.2458 | E40: =D40-C40 -> 0.009 | F40: =E40/B40*1000*1000 -> 100 | G40: 327.453 | H40: 1.2514083 | I40: =H40/B40*1000 -> 13.904536 | J40: 8.576 | K40: 0.0104 | N40: 446 | O40: 45136.636 | P40: 37.7552 | Q40: 7.7268 | R40: 35.4 | S40: 7.6048 | T40: 37.7552 | U40: 7.7268
...

Sheet Grab Samples
A1: Grab Samples | B1: Volume filtered (mL) | C1: pre-filter weight (g) | D1: post-filter weight (g) | E1: Total sediment on filter - (inorganic + organic) (g) | F1: SS concentration (mg/L) | G1: LISST concentration (uL/L) | H1: mgC | I1: POC | J1: DOC | K1: PP (mg/L) | L1: SRP | M1: TP | N1: Lab ID | O1: DateTime | P1: Grab Samples
A2: GSU1 | B2: 287.25 | C2: 0.2442 | D2: 0.2456 | E2: =D2-C2 -> 0.0014 | F2: =('Grab Samples'!E2*1000)/('Grab Samples'!B2/1000) -> 4.8738033 | G2: 0 | H2: 1.0464373 | I2: =H2/('Grab Samples'!B2/1000) -> 3.6429498 | L2: 0.03 | M2: 0.037 | N2: VC-BER-7 | O2: 44394 | P2: Summer 2021
A3: GSD1 | B3: 159.59 | C3: 0.2402 | D3: 0.2403 | E3: =D3-C3 -> 0.0001 | F3: =('Grab Samples'!E3*1000)/('Grab Samples'!B3/1000) -> 0.62660568 | G3: 0 | H3: 0.39719241 | I3: =H3/('Grab Samples'!B3/1000) -> 2.4888302 | L3: 0.028 | M3: 0.037 | N3: VC-BER-8 | O3: 44394 | P3: Spring 2022
A4: GSU2 | B4: 134.51 | C4: 0.2412 | D4: 0.2418 | E4: =D4-C4 -> 0.0006 | F4: =('Grab Samples'!E4*1000)/('Grab Samples'!B4/1000) -> 4.4606349 | G4: 0 | H4: 0.33234238 | I4: =H4/('Grab Samples'!B4/1000) -> 2.4707634 | L4: 0.022 | M4: 0.026 | N4: VC-BER-9 | O4: 44396 | P4: Summer 2022
A5: GSD2 | B5: 117.23 | C5: 0.2407 | D5: 0.2416 | E5: =D5-C5 -> 0.0009 | F5: =('Grab Samples'!E5*1000)/('Grab Samples'!B5/1000) -> 7.6772157 | G5: 0 | H5: 0.33481119 | I5: =H5/('Grab Samples'!B5/1000) -> 2.8560197 | L5: 0.025 | M5: 0.025 | N5: VC-BER-10 | O5: 44396 | P5: Spring 2023
A6: GSU4 | B6: 333.45 | C6: 0.241 | D6: 0.2425 | E6: =D6-C6 -> 0.0015 | F6: =('Grab Samples'!E6*1000)/('Grab Samples'!B6/1000) -> 4.4984256 | G6: 0 | H6: 0.49779419 | I6: =H6/('Grab Samples'!B6/1000) -> 1.4928601 | L6: 0.024 | M6: 0.022 | N6: VC-BER-11 | O6: 44413 | P6: Summer 2023
A7: GSD4 | B7: 318 | C7: 0.2416 | D7: 0.2433 | E7: =D7-C7 -> 0.0017 | F7: =('Grab Samples'!E7*1000)/('Grab Samples'!B7/1000) -> 5.3459119 | G7: 0 | H7: 0.4771077 | I7: =H7/('Grab Samples'!B7/1000) -> 1.5003387 | L7: 0.024 | M7: 0.023 | N7: VC-BER-12 | O7: 44413
A8: GSU5 | B8: 293.42 | C8: 0.24 | D8: 0.2436 | E8: =D8-C8 -> 0.0036 | F8: =('Grab Samples'!E8*1000)/('Grab Samples'!B8/1000) -> 12.269102 | G8: 0 | H8: 0.75074101 | I8: =H8/('Grab Samples'!B8/1000) -> 2.5585884 | L8: 0.022 | M8: 0.024 | N8: VC-BER-13 | O8: 44421
A9: GSD5 | B9: 341.46 | C9: 0.2407 | D9: 0.2424 | E9: =D9-C9 -> 0.0017 | F9: =('Grab Samples'!E9*1000)/('Grab Samples'!B9/1000) -> 4.9786212 | G9: 0 | H9: 0.58988878 | I9: =H9/('Grab Samples'!B9/1000) -> 1.7275487 | L9: 0.021 | M9: 0.022 | N9: VC-BER-14 | O9: 44421 | Q9: Starting Concentrations for hysteresis patterns
A10: GSU6 | B10: 119.13 | C10: 0.2396 | D10: 0.2404 | E10: =D10-C10 -> 0.0008 | F10: =('Grab Samples'!E10*1000)/('Grab Samples'!B10/1000) -> 6.715353 | G10: 0 | J10: 1.482 | N10: 121 | O10: 44632 | R10: SS (uL/L) | S10: SSC (mg/L) | T10: SRP (mg/L) | U10: TP (mg/L) | V10: PP (mg/L) | W10: POC (mg/L) | X10: DOC (mg/L)
A11: GSD6 | B11: 121.65 | C11: 0.2363 | D11: 0.2373 | E11: =D11-C11 -> 0.001 | F11: =('Grab Samples'!E11*1000)/('Grab Samples'!B11/1000) -> 8.2203042 | G11: 0 | J11: 1.538 | N11: 120 | O11: 44632 | Q11: Storm 1 (2021) | R11: 0 | S11: =AVERAGE(F2:F5) -> 4.4095649 | T11: =AVERAGE(L2:L5) -> 0.02625 | U11: =AVERAGE(M2:M5) -> 0.03125 | V11: 0 | W11: =AVERAGE(I2:I5) -> 2.8646408 | X11: =AVERAGE(J10:J13) -> 1.754
A12: GSU7 | B12: 119.19 | C12: 0.2397 | D12: 0.2409 | E12: =D12-C12 -> 0.0012 | F12: =('Grab Samples'!E12*1000)/('Grab Samples'!B12/1000) -> 10.067959 | G12: 0 | J12: 2.238 | N12: 129 | O12: 44638 | Q12: Storm 2 (2022) | R12: 0 | S12: =AVERAGE(F14:F15) -> 2.9274424 | T12: =AVERAGE(L14:L15) -> 0.0019785 | U12: =AVERAGE(M6:M9) -> 0.02275 | V12: 0 | W12: =AVERAGE(I6:I9) -> 1.819834 | X12: =AVERAGE(J14:J15) -> 2.8035
A13: GSD7 | B13: 120.77 | C13: 0.2383 | D13: 0.239 | E13: =D13-C13 -> 0.0007 | F13: =('Grab Samples'!E13*1000)/('Grab Samples'!B13/1000) -> 5.7961414 | G13: 0 | J13: 1.758 | N13: 124 | O13: 44638 | Q13: Storm 3 (2022) | R13: 0 | S13: =AVERAGE(F14:F15) -> 2.9274424 | T13: =AVERAGE(L14:L15) -> 0.0019785 | U13: =AVERAGE(M6:M9) -> 0.02275 | V13: 0 | W13: ='Summer '!I21 -> 1.5244914 | X13: =AVERAGE(J14:J15) -> 2.8035
A14: GSU8 | B14: 119.31 | C14: 0.2397 | D14: 0.2403 | E14: =D14-C14 -> 0.0006 | F14: =('Grab Samples'!E14*1000)/('Grab Samples'!B14/1000) -> 5.0289163 | G14: 0 | J14: 3.294 | L14: 0.0022416 | N14: 126 | O14: 44754 | Q14: Storm 4 (2023) | R14: 0 | S14: =F36 -> 13.333333 | V14: 0 | W14: =I36 -> 0.087679832 | X14: =AVERAGE(J14:J15) -> 2.8035
A15: GSD8 | B15: 121.07 | C15: 0.241 | D15: 0.2411 | E15: =D15-C15 -> 0.0001 | F15: =('Grab Samples'!E15*1000)/('Grab Samples'!B15/1000) -> 0.82596845 | G15: 0 | J15: 2.313 | L15: 0.0017154 | N15: 123 | O15: 44754 | Q15: Storm 5 (2023) | R15: 0 | S15: =F36 -> 13.333333 | V15: 0 | W15: =I36 -> 0.087679832 | X15: =AVERAGE(J18:J19) -> 3.451
A16: GSU9 | B16: 120.11 | C16: 0.2368 | D16: 0.2375 | E16: =D16-C16 -> 0.0007 | F16: =('Grab Samples'!E16*1000)/('Grab Samples'!B16/1000) -> 5.827991 | G16: 0 | J16: 3.639 | L16: 0.0022416 | N16: 127 | O16: 44784 | Q16: Storm 6 (2023) | R16: 0 | S16: =AVERAGE(F37:F38) -> 5.5238095 | V16: 0 | W16: =I36 -> 0.087679832 | X16: =AVERAGE(J37:J38) -> 1.1215
A17: GSD9 | B17: 121.37 | C17: 0.2329 | D17: 0.2331 | E17: =D17-C17 -> 0.0002 | F17: =('Grab Samples'!E17*1000)/('Grab Samples'!B17/1000) -> 1.6478537 | G17: 0 | J17: 3.156 | L17: 0.0010138 | N17: 122 | O17: 44784 | Q17: Storm 7 (2023) | R17: 0 | S17: =AVERAGE(F37:F38) -> 5.5238095 | V17: 0 | W17: =I36 -> 0.087679832 | X17: =AVERAGE(J37:J38) -> 1.1215
A18: GSU10 | B18: 107.41 | C18: 0.2375 | D18: 0.2375 | E18: =D18-C18 -> 0 | F18: =('Grab Samples'!E18*1000)/('Grab Samples'!B18/1000) -> 0 | G18: 0 | J18: 3.691 | N18: 128 | O18: 44797
A19: GSD10 | B19: 104.74 | C19: 0.2333 | D19: 0.2334 | E19: =D19-C19 -> 0.0001 | F19: =('Grab Samples'!E19*1000)/('Grab Samples'!B19/1000) -> 0.95474508 | G19: 0 | J19: 3.211 | N19: 125 | O19: 44797
A20: GSUB11 | B20: 119.19 | C20: 0.2304 | D20: 0.233 | E20: =D20-C20 -> 0.0026 | F20: =('Grab Samples'!E20*1000)/('Grab Samples'!B20/1000) -> 21.813911 | G20: 0 | J20: 2.319 | N20: 136 | O20: 45003
A21: GSUT11 | B21: 200 | C21: 0.223 | D21: 0.2288 | E21: =D21-C21 -> 0.0058 | F21: =('Grab Samples'!E21*1000)/('Grab Samples'!B21/1000) -> 29 | G21: 0 | J21: 2.254 | N21: 137 | O21: 45003
A22: GSDB 11 | B22: 120.77 | C22: 0.235 | D22: 0.236 | E22: =D22-C22 -> 0.001 | F22: =('Grab Samples'!E22*1000)/('Grab Samples'!B22/1000) -> 8.280202 | G22: 0 | J22: 2.438 | N22: 134 | O22: 45003
A23: GSDT 11 | B23: 190 | C23: 0.233 | D23: 0.2338 | E23: =D23-C23 -> 0.0008 | F23: =('Grab Samples'!E23*1000)/('Grab Samples'!B23/1000) -> 4.2105263 | G23: 0 | J23: 2.302 | N23: 135 | O23: 45003
A24: GSUB12 | B24: 210 | C24: 0.235 | D24: 0.2404 | E24: =D24-C24 -> 0.0054 | F24: =('Grab Samples'!E24*1000)/('Grab Samples'!B24/1000) -> 25.714286 | G24: 0 | J24: 2.197 | N24: 140 | O24: 45004
A25: GSUT12 | B25: 200 | C25: 0.233 | D25: 0.2352 | E25: =D25-C25 -> 0.0022 | F25: =('Grab Samples'!E25*1000)/('Grab Samples'!B25/1000) -> 11 | G25: 0 | J25: 2.263 | N25: 141 | O25: 45004
A26: GSDB12 | B26: 200 | C26: 0.235 | D26: 0.2365 | E26: =D26-C26 -> 0.0015 | F26: =('Grab Samples'!E26*1000)/('Grab Samples'!B26/1000) -> 7.5 | G26: 0 | J26: 2.288 | N26: 138 | O26: 45004
A27: GSDT12 | B27: 190 | C27: 0.23 | D27: 0.2319 | E27: =D27-C27 -> 0.0019 | F27: =('Grab Samples'!E27*1000)/('Grab Samples'!B27/1000) -> 10 | G27: 0 | J27: 2.179 | N27: 139 | O27: 45004
A28: GSUB13 | B28: 200 | C28: 0.235 | D28: 0.2424 | E28: =D28-C28 -> 0.0074 | F28: =('Grab Samples'!E28*1000)/('Grab Samples'!B28/1000) -> 37 | J28: 2.135 | N28: 144 | O28: 45007
A29: GSUT13 | B29: 190 | C29: 0.2333 | D29: 0.237 | E29: =D29-C29 -> 0.0037 | F29: =('Grab Samples'!E29*1000)/('Grab Samples'!B29/1000) -> 19.473684 | J29: 2.148 | N29: 143 | O29: 45007
A30: GSDB13 | B30: 200 | C30: 0.222 | D30: 0.229 | E30: =D30-C30 -> 0.007 | F30: =('Grab Samples'!E30*1000)/('Grab Samples'!B30/1000) -> 35 | J30: 2.196 | N30: 142 | O30: 45007
A31: GSDT13 | B31: 200 | C31: 0.236 | D31: 0.2366 | E31: =D31-C31 -> 0.0006 | F31: =('Grab Samples'!E31*1000)/('Grab Samples'!B31/1000) -> 3 | J31: 2.067 | N31: 145 | O31: 45007
A32: GSUB14 | B32: 150 | C32: 0.235 | D32: 0.2367 | E32: =D32-C32 -> 0.0017 | F32: =('Grab Samples'!E32*1000)/('Grab Samples'!B32/1000) -> 11.333333 | G32: 115.205 | J32: 4.384 | N32: 132 | O32: 45029
A33: GSUT14 | B33: 145 | C33: 0.225 | D33: 0.2274 | E33: =D33-C33 -> 0.0024 | F33: =('Grab Samples'!E33*1000)/('Grab Samples'!B33/1000) -> 16.551724 | G33: 106.28 | J33: 4.49 | N33: 133 | O33: 45029
A34: GSDT14 | B34: 150 | C34: 0.239 | D34: 0.24 | E34: =D34-C34 -> 0.001 | F34: =('Grab Samples'!E34*1000)/('Grab Samples'!B34/1000) -> 6.6666667 | G34: 118.6825 | J34: 4.493 | N34: 131 | O34: 45029
A35: GSDB14 | B35: 200 | C35: 0.234 | D35: 0.2353 | E35: =D35-C35 -> 0.0013 | F35: =('Grab Samples'!E35*1000)/('Grab Samples'!B35/1000) -> 6.5 | G35: 73.135 | J35: 4.441 | N35: 130 | O35: 45029
A36: GSU15 | B36: 150 | C36: 0.2332 | D36: 0.2352 | E36: =D36-C36 -> 0.002 | F36: =('Grab Samples'!E36*1000)/('Grab Samples'!B36/1000) -> 13.333333 | G36: 0 | H36: 0.013151975 | I36: =H36/('Grab Samples'!B36/1000) -> 0.087679832 | N36: 436 | O36: 45127
A37: GSU16 | B37: 140 | C37: 0.2331 | D37: 0.2339 | E37: =D37-C37 -> 0.0008 | F37: =('Grab Samples'!E37*1000)/('Grab Samples'!B37/1000) -> 5.7142857 | G37: 0 | J37: 1.127 | N37: 475 | O37: 45154
A38: GSD16 | B38: 150 | C38: 0.2403 | D38: 0.2411 | E38: =D38-C38 -> 0.0008 | F38: =('Grab Samples'!E38*1000)/('Grab Samples'!B38/1000) -> 5.3333333 | G38: 0 | J38: 1.116 | N38: 474 | O38: 45153

Sheet Experiments
A1: Sample ID | B1: Volume filtered (mL) | C1: pre-filter weight (g) | D1: post-filter weight (g) | E1: Total sediment on filter - (inorganic + organic) (g) | F1: SS concentration (mg/L) | G1: LISST concentration (uL/L) | H1: mgC | I1: POC | J1: DOC | K1: Lab ID | L1: DateTime
A2: Exp 1 | B2: 347.29 | C2: 0.2397 | D2: 0.2409 | E2: =D2-C2 -> 0.0012 | F2: =E2/B2*1000*1000 -> 3.4553255 | G2: 0 | H2: 0.382681 | I2: =H2/B2*1000 -> 1.1019062 | K2: VC-BER-32 | L2: 0.72638889 | N2: 2021 Armor Removal Experiment
A3: Exp 2 | B3: 421.38 | C3: 0.2385 | D3: 0.2468 | E3: =D3-C3 -> 0.0083 | F3: =E3/B3*1000*1000 -> 19.697185 | G3: 0 | H3: 0.31336973 | I3: =H3/B3*1000 -> 0.74367491 | K3: VC-BER-33 | L3: 0.7285 | N3: Exp 1 - Aug 2
A4: Exp 3 | B4: 368.46 | C4: 0.242 | D4: 0.2614 | E4: =D4-C4 -> 0.0194 | F4: =E4/B4*1000*1000 -> 52.651577 | G4: 37.18 | H4: 3.1352132 | I4: =H4/B4*1000 -> 8.5089648 | K4: VC-BER-34 | L4: 0.73061111 | N4: Exp 2 - Aug 2
A5: Exp 4 | B5: 334.69 | C5: 0.2387 | D5: 0.2688 | E5: =D5-C5 -> 0.0301 | F5: =E5/B5*1000*1000 -> 89.933969 | G5: 52.18 | H5: 3.4862856 | I5: =H5/B5*1000 -> 10.416462 | K5: VC-BER-35 | L5: 0.73272222 | N5: Exp 3 - Aug 2
A6: Exp 5 | B6: 397.99 | C6: 0.2418 | D6: 0.2711 | E6: =D6-C6 -> 0.0293 | F6: =E6/B6*1000*1000 -> 73.61994 | G6: 80.87 | H6: 3.8748706 | I6: =H6/B6*1000 -> 9.7361003 | K6: VC-BER-36 | L6: 0.73483333 | N6: Exp 4 - Aug 3
A7: Exp 6 | B7: 331.54 | C7: 0.2427 | D7: 0.3223 | E7: =D7-C7 -> 0.0796 | F7: =E7/B7*1000*1000 -> 240.09169 | G7: 220.02 | H7: 12.816921 | I7: =H7/B7*1000 -> 38.658748 | K7: VC-BER-37 | L7: 0.73694444 | N7: Exp 5 - Aug 3
A8: Exp 7 | B8: 424.06 | C8: 0.242 | D8: 0.2732 | E8: =D8-C8 -> 0.0312 | F8: =E8/B8*1000*1000 -> 73.574494 | G8: 41.39 | H8: 2.6905717 | I8: =H8/B8*1000 -> 6.3447902 | K8: VC-BER-38 | L8: 0.73905556 | N8: Exp 6 - Aug 4
A9: Exp 8 | B9: 417.94 | C9: 0.2429 | D9: 0.2516 | E9: =D9-C9 -> 0.0087 | F9: =E9/B9*1000*1000 -> 20.816385 | G9: 0 | H9: 0.8273147 | I9: =H9/B9*1000 -> 1.9795059 | K9: VC-BER-39 | L9: 0.74116667 | N9: Exp 7
A10: Exp 9 | B10: 475.46 | C10: 0.2399 | D10: 0.2483 | E10: =D10-C10 -> 0.0084 | F10: =E10/B10*1000*1000 -> 17.667101 | G10: 0 | H10: 1.5306314 | I10: =H10/B10*1000 -> 3.2192643 | K10: VC-BER-40 | L10: 0.74327778 | N10: Exp 8 - Aug 5
A11: Exp 10 | B11: 369.59 | C11: 0.243 | D11: 0.2489 | E11: =D11-C11 -> 0.0059 | F11: =E11/B11*1000*1000 -> 15.963635 | G11: 0 | H11: 1.1106837 | I11: =H11/B11*1000 -> 3.005178 | K11: VC-BER-41 | L11: 0.74538889
A12: Exp 11 | B12: 254.71 | C12: 0.2421 | D12: 0.2439 | E12: =D12-C12 -> 0.0018 | F12: =E12/B12*1000*1000 -> 7.0668604 | G12: 0 | H12: 0.39802114 | I12: =H12/B12*1000 -> 1.5626444 | K12: VC-BER-42 | L12: 0.7475
A13: Exp 12 | B13: 289.46 | C13: 0.2396 | D13: 0.2432 | E13: =D13-C13 -> 0.0036 | F13: =E13/B13*1000*1000 -> 12.436952 | G13: 0 | H13: 0.83265553 | I13: =H13/B13*1000 -> 2.8765824 | K13: VC-BER-43 | L13: 0.74961111
A14: Exp 13 | B14: 345.87 | C14: 0.2368 | D14: 0.2396 | E14: =D14-C14 -> 0.0028 | F14: =E14/B14*1000*1000 -> 8.0955272 | G14: 0 | H14: 0.76527716 | I14: =H14/B14*1000 -> 2.212615 | K14: VC-BER-44 | L14: 0.75172222
A15: Exp 14 | B15: 368.48 | C15: 0.2354 | D15: 0.2394 | E15: =D15-C15 -> 0.004 | F15: =E15/B15*1000*1000 -> 10.855406 | G15: 0 | H15: 0.94608429 | I15: =H15/B15*1000 -> 2.5675323 | K15: VC-BER-45 | L15: 0.75383333
A16: Exp 15 | B16: 344.91 | C16: 0.2391 | D16: 0.2412 | E16: =D16-C16 -> 0.0021 | F16: =E16/B16*1000*1000 -> 6.0885448 | G16: 0 | H16: 0.76957728 | I16: =H16/B16*1000 -> 2.2312408 | K16: VC-BER-46 | L16: 0.75594444
A17: Exp 16 | B17: 340.19 | C17: 0.2411 | D17: 0.245 | E17: =D17-C17 -> 0.0039 | F17: =E17/B17*1000*1000 -> 11.464182 | G17: 0 | H17: 0.94659765 | I17: =H17/B17*1000 -> 2.7825558 | K17: VC-BER-47 | L17: 0.75805556
A18: Exp 1 C B#1 | B18: 105.96 | C18: 0.2385 | D18: 0.2562 | E18: =D18-C18 -> 0.0177 | F18: =E18/B18*1000*1000 -> 167.04417 | G18: 97.69 | H18: 1.1628606 | I18: =H18/B18*1000 -> 10.974524 | J18: 2.64 | K18: 1 | L18: 0.49802083
A19: Exp 1 C B#2 | B19: 115.11 | C19: 0.2422 | D19: 0.2589 | E19: =D19-C19 -> 0.0167 | F19: =E19/B19*1000*1000 -> 145.07862 | G19: 347.61 | H19: 1.4193635 | I19: =H19/B19*1000 -> 12.330497 | J19: 2.384 | K19: 2 | L19: 0.49815972
A20: Exp 1 C B#3 | B20: 119.52 | C20: 0.2406 | D20: 0.2497 | E20: =D20-C20 -> 0.0091 | F20: =E20/B20*1000*1000 -> 76.137885 | G20: 191.85 | J20: 2.284 | K20: 3 | L20: 0.49828704
A21: Exp 1 C B#4 | B21: 118.83 | C21: 0.2405 | D21: 0.2462 | E21: =D21-C21 -> 0.0057 | F21: =E21/B21*1000*1000 -> 47.967685 | G21: 176.97 | H21: 0.59024633 | I21: =H21/B21*1000 -> 4.9671491 | J21: 2.423 | K21: 4 | L21: 0.49840278
A22: Exp 1 C B#5 | B22: 120.31 | C22: 0.2393 | D22: 0.2474 | E22: =D22-C22 -> 0.0081 | F22: =E22/B22*1000*1000 -> 67.326074 | G22: 127.27 | H22: 1.0695984 | I22: =H22/B22*1000 -> 8.8903535 | J22: 2.488 | K22: 5 | L22: 0.49853009
A23: Exp 1 C B#6 | B23: 120.78 | C23: 0.2394 | D23: 0.2468 | E23: =D23-C23 -> 0.0074 | F23: =E23/B23*1000*1000 -> 61.268422 | G23: 83.04 | J23: 2.473 | K23: 6 | L23: 0.49865741
A24: Exp 1 C B#7 | B24: 120.15 | C24: 0.2416 | D24: 0.2465 | E24: =D24-C24 -> 0.0049 | F24: =E24/B24*1000*1000 -> 40.782355 | G24: 68.69 | J24: 2.314 | K24: 7 | L24: 0.49877315
A25: Exp 1 C B#8 | B25: 122.26 | C25: 0.2415 | D25: 0.2468 | E25: =D25-C25 -> 0.0053 | F25: =E25/B25*1000*1000 -> 43.350237 | G25: 62.04 | J25: 2.402 | K25: 8 | L25: 0.49890046
A26: Exp 1 C B#9 | B26: 120.51 | C26: 0.2387 | D26: 0.2432 | E26: =D26-C26 -> 0.0045 | F26: =E26/B26*1000*1000 -> 37.341299 | G26: 61.07 | J26: 2.278 | K26: 9 | L26: 0.49900463
A27: Exp 1 C B#10 | B27: 121.55 | C27: 0.2397 | D27: 0.2424 | E27: =D27-C27 -> 0.0027 | F27: =E27/B27*1000*1000 -> 22.213081 | G27: 48.37 | J27: 2.273 | K27: 10 | L27: 0.49912037
A28: Exp 1 C B#11 | B28: 120.93 | C28: 0.2418 | D28: 0.2443 | E28: =D28-C28 -> 0.0025 | F28: =E28/B28*1000*1000 -> 20.673117 | G28: 29.69 | J28: 2.301 | K28: 11 | L28: 0.49923611
A29: Exp 1 C B#12 | B29: 119.54 | C29: 0.2304 | D29: 0.2319 | E29: =D29-C29 -> 0.0015 | F29: =E29/B29*1000*1000 -> 12.548101 | G29: 28.69 | H29: 0.38750065 | I29: =H29/B29*1000 -> 3.2415982 | J29: 2.313 | K29: 12 | L29: 0.49935185
A30: Exp 1 C B#13 | B30: 121.19 | C30: 0.2356 | D30: 0.2369 | E30: =D30-C30 -> 0.0013 | F30: =E30/B30*1000*1000 -> 10.726958 | G30: 22.43 | J30: 2.308 | K30: 13 | L30: 0.49945602
A31: Exp 1 C B#14 | B31: 121.5 | C31: 0.2375 | D31: 0.2383 | E31: =D31-C31 -> 0.0008 | F31: =E31/B31*1000*1000 -> 6.5843621 | G31: 0 | J31: 2.214 | K31: 14 | L31: 0.49958333
A32: Exp 2 C B#1 | B32: 122.7 | C32: 0.2318 | D32: 0.2346 | E32: =D32-C32 -> 0.0028 | F32: =E32/B32*1000*1000 -> 22.819886 | G32: 31.7 | H32: 0.40833207 | I32: =H32/B32*1000 -> 3.3278898 | J32: 2.718 | K32: 15 | L32: 0.078923611
A33: Exp 2 C B#2 | B33: 121.56 | C33: 0.2399 | D33: 0.248 | E33: =D33-C33 -> 0.0081 | F33: =E33/B33*1000*1000 -> 66.633761 | G33: 93.36 | H33: 0.80993612 | I33: =H33/B33*1000 -> 6.6628506 | J33: 2.682 | K33: 16 | L33: 0.079050926
A34: Exp 2 C B#3 | B34: 122.43 | C34: 0.2381 | D34: 0.258 | E34: =D34-C34 -> 0.0199 | F34: =E34/B34*1000*1000 -> 162.54186 | G34: 229.76 | H34: 1.4742054 | I34: =H34/B34*1000 -> 12.041211 | J34: 2.644 | K34: 17 | L34: 0.079166667
A35: Exp 2 C B#4 | B35: 122.82 | C35: 0.236 | D35: 0.247 | E35: =D35-C35 -> 0.011 | F35: =E35/B35*1000*1000 -> 89.561961 | G35: 127.13 | J35: 2.752 | K35: 18 | L35: 0.079282407
A36: Exp 2 C B#5 | B36: 121.09 | C36: 0.2417 | D36: 0.2523 | E36: =D36-C36 -> 0.0106 | F36: =E36/B36*1000*1000 -> 87.538195 | G36: 187.73 | H36: 0.97576711 | I36: =H36/B36*1000 -> 8.0581973 | J36: 2.808 | K36: 19 | L36: 0.079398148
A37: Exp 2 C B#6 | B37: 120.25 | C37: 0.2315 | D37: 0.2396 | E37: =D37-C37 -> 0.0081 | F37: =E37/B37*1000*1000 -> 67.359667 | G37: 112.47 | J37: 3.009 | K37: 20 | L37: 0.079513889
A38: Exp 2 C B#7 | B38: 121.68 | C38: 0.2359 | D38: 0.2434 | E38: =D38-C38 -> 0.0075 | F38: =E38/B38*1000*1000 -> 61.637081 | G38: 84.69 | J38: 2.784 | K38: 21 | L38: 0.07962963
A39: Exp 2 C B#8 | B39: 122.23 | C39: 0.2365 | D39: 0.2411 | E39: =D39-C39 -> 0.0046 | F39: =E39/B39*1000*1000 -> 37.633969 | G39: 97.42 | H39: 0.61806169 | I39: =H39/B39*1000 -> 5.0565466 | J39: 2.756 | K39: 22 | L39: 0.07974537
A40: Exp 2 C B#9 | B40: 120.76 | C40: 0.2407 | D40: 0.2467 | E40: =D40-C40 -> 0.006 | F40: =E40/B40*1000*1000 -> 49.685326 | G40: 78.81 | H40: 0.45121105 | I40: =H40/B40*1000 -> 3.736428 | J40: 2.804 | K40: 23 | L40: 0.079861111
...
